#VRML_SIM R2023b utf8

EXTERNPROTO "https://raw.githubusercontent.com/cyberbotics/webots/R2023b/projects/objects/backgrounds/protos/TexturedBackground.proto"
EXTERNPROTO "https://raw.githubusercontent.com/cyberbotics/webots/R2023b/projects/objects/backgrounds/protos/TexturedBackgroundLight.proto"
EXTERNPROTO "https://raw.githubusercontent.com/cyberbotics/webots/R2023b/projects/objects/floors/protos/RectangleArena.proto"
EXTERNPROTO "https://raw.githubusercontent.com/cyberbotics/webots/R2023b/projects/objects/advertising_board/protos/AdvertisingBoard.proto"
EXTERNPROTO "https://raw.githubusercontent.com/cyberbotics/webots/R2023b/projects/appearances/protos/Cardboard.proto"
EXTERNPROTO "https://raw.githubusercontent.com/cyberbotics/webots/R2023b/projects/bounding_objects/protos/TorusBoundingObject.proto"
EXTERNPROTO "https://raw.githubusercontent.com/cyberbotics/webots/R2023b/projects/appearances/protos/Parquetry.proto"

WorldInfo {
  gravity 9.8
  CFM 1e-07
  ERP 0.8
  basicTimeStep 1
  FPS 30
  optimalThreadCount 8
  contactProperties [
    ContactProperties {
      coulombFriction [
        0.9
      ]
      bounce 0.3
      bounceVelocity 0.003
      softERP 0.42
      softCFM 0.000208
    }
  ]
}
Viewpoint {
  orientation -0.22346882612599073 -0.015577938803226835 0.9745865849541099 3.2772730588683396
  position 2.2995924911069485 -4.249369037694479 2.397362001975927
}
TexturedBackground {
}
TexturedBackgroundLight {
  luminosity 0.8
}
RectangleArena {
  translation -0.246845 -3.09843 4.44089e-16
  rotation 0 0 -1 0
  floorSize 50 50
  floorAppearance Parquetry {
    type "light strip"
    colorOverride 0.682353 0.670588 0.662745
  }
}
TexturedBackgroundLight {
  luminosity 0.2
}
AdvertisingBoard {
  translation -13.0277 -4.19533 -4.9738e-14
  rotation 0 0 1 3.14159
  recognitionColors [
    1 0.847059 0.933333
    0.74902 0.737255 0.741176
  ]
  displayWidth 7
  frameColor 0.666667 0.666667 0.498039
  poleColor 0.862745 0.886275 0.717647
  baseRatio 3
}
DEF UnitreeH1 Robot {
  translation -0.950212126399238 -5.057005094813062 0.9699260479365635
  rotation 0.008548227331837124 -0.997510867751187 0.06999283197411897 0.03905539914037289
  children [
    GPS {
      name "gps_upperBody"
    }
    InertialUnit {
      name "inertial_unit_upperBody"
    }
    Gyro {
      name "gyro_upperBody"
    }
    Accelerometer {
      name "accelerometer_upperBody"
    }
    DEF pelvis_visual CadShape {
      url [
        "../meshes/pelvis.dae"
      ]
    }
    HingeJoint {
      jointParameters HingeJointParameters {
        position -1.7658389107770348e-07
        axis 0 0 1
        anchor 0 0.0875 -0.1742
      }
      device [
        RotationalMotor {
          name "left_hip_yaw_joint"
          maxVelocity 23
          minPosition -0.43
          maxPosition 0.43
          maxTorque 220
        }
        PositionSensor {
          name "left_hip_yaw_joint_sensor"
        }
      ]
      endPoint Solid {
        translation 1.1102236383590303e-16 0.08750000000000036 -0.17419999999999947
        rotation 0 0 -1 1.7631291696726137e-07
        children [
          DEF left_hip_yaw_link_visual CadShape {
            url [
              "../meshes/left_hip_yaw_link.dae"
            ]
          }
          HingeJoint {
            jointParameters HingeJointParameters {
              position 3.2294170072841557e-06
              anchor 0.039468 0 0
            }
            device [
              RotationalMotor {
                name "left_hip_roll_joint"
                maxVelocity 23
                minPosition -0.43
                maxPosition 0.43
                maxTorque 220
              }
              PositionSensor {
                name "left_hip_roll_joint_sensor"
              }
            ]
            endPoint Solid {
              translation 0.039467999999999975 5.551330245483892e-17 -6.661336355029608e-16
              rotation 0.9999999999999999 0 0 3.229394835587797e-06
              children [
                DEF left_hip_roll_link_visual CadShape {
                  url [
                    "../meshes/left_hip_roll_link.dae"
                  ]
                }
                HingeJoint {
                  jointParameters HingeJointParameters {
                    position -0.2999992367291291
                    axis 0 1 0
                    anchor 0 0.11536 0
                  }
                  device [
                    RotationalMotor {
                      name "left_hip_pitch_joint"
                      maxVelocity 23
                      minPosition -3.14
                      maxPosition 2.53
                      maxTorque 220
                    }
                    PositionSensor {
                      name "left_hip_pitch_joint_sensor"
                    }
                  ]
                  endPoint Solid {
                    translation 5.55111668095082e-16 0.1153600000000008 2.220442154682759e-16
                    rotation 0 -0.9999999999999999 0 0.2999992367291284
                    children [
                      DEF left_hip_pitch_link_visual CadShape {
                        url [
                          "../meshes/left_hip_pitch_link.dae"
                        ]
                      }
                      HingeJoint {
                        jointParameters HingeJointParameters {
                          position 0.8000326022124677
                          axis 0 1 0
                          anchor 0 0 -0.4
                        }
                        device [
                          RotationalMotor {
                            name "left_knee_joint"
                            maxVelocity 14
                            minPosition -0.26
                            maxPosition 2.05
                            maxTorque 360
                          }
                          PositionSensor {
                            name "left_knee_joint_sensor"
                          }
                        ]
                        endPoint Solid {
                          translation -2.1820535852945603e-16 0 -0.40000000000000036
                          rotation 0 1 0 0.8000326022124676
                          children [
                            DEF left_knee_link_visual CadShape {
                              url [
                                "../meshes/left_knee_link.dae"
                              ]
                            }
                            HingeJoint {
                              jointParameters HingeJointParameters {
                                position -0.46110103767336397
                                axis 0 1 0
                                anchor 0 0 -0.4
                              }
                              device [
                                RotationalMotor {
                                  name "left_ankle_joint"
                                  maxVelocity 9
                                  minPosition -0.9000211187369112
                                  maxPosition 0.52
                                  maxTorque 45
                                }
                                PositionSensor {
                                  name "left_ankle_joint_sensor"
                                }
                              ]
                              endPoint DEF LeftFootSole Solid {
                                translation 0.07204003245134173 -1.776356839400192e-15 -0.4200398035022636
                                rotation 0 -0.9999999999999999 0 0.46110103767336397
                                children [
                                  TouchSensor {
                                    translation 1.83036719114682e-09 -1.0569776165425537e-08 4.316185828086294e-07
                                    rotation -0.18416720224591485 0.9818954435802694 0.04431455170954793 1.0464795271324494e-08
                                    name "left_foot_sole_touch_sensor_3d"
                                    boundingObject Box {
                                      size 0.28 0.03 0.024
                                    }
                                    physics Physics {
                                      density -1
                                      mass 0.001
                                      centerOfMass [
                                        0 0 0
                                      ]
                                      inertiaMatrix [
                                        1.23e-06 6.581333333333335e-05 6.608333333333334e-05
                                        0 0 0
                                      ]
                                    }
                                    type "force-3d"
                                  }
                                  DEF left_ankle_torque_sensor HingeJoint {
                                    jointParameters HingeJointParameters {
                                      axis 0 1 0
                                    }
                                    device [
                                      RotationalMotor {
                                        name "left_ankle_torque_sensor_pitch"
                                      }
                                    ]
                                    endPoint Solid {
                                      rotation 0 1 0 0
                                      children [
                                        Solid {
                                          children [
                                            Shape {
                                              appearance Appearance {
                                                material Material {
                                                  diffuseColor 0.8 0.129412 0.6
                                                }
                                              }
                                              geometry Box {
                                                size 0.001 0.001 0.001
                                              }
                                            }
                                          ]
                                        }
                                      ]
                                    }
                                  }
                                  Pose {
                                    translation -0.046 0 0.056
                                    children [
                                      DEF left_ankle_link_visual CadShape {
                                        url [
                                          "../meshes/left_ankle_link.dae"
                                        ]
                                      }
                                    ]
                                  }
                                ]
                                name "left_ankle_link"
                                boundingObject Box {
                                  size 0.28 0.03 0.024
                                }
                                physics Physics {
                                  density -1
                                  mass 0.474
                                  centerOfMass [
                                    0.042575 -1e-06 -0.044672
                                  ]
                                  inertiaMatrix [
                                    0.000159668 0.002900286 0.002805438
                                    0 0 0
                                  ]
                                }
                              }
                            }
                          ]
                          name "left_knee_link"
                          boundingObject Cylinder {
                            height 0.2
                            radius 0.05
                          }
                          physics Physics {
                            density -1
                            mass 1.721
                            centerOfMass [
                              -0.00136 -0.00512 -0.1384
                            ]
                            inertiaMatrix [
                              0.012205 0.012509 0.0020629
                              0 0 0
                            ]
                          }
                        }
                      }
                    ]
                    name "left_hip_pitch_link"
                    boundingObject Cylinder {
                      height 0.2
                      radius 0.05
                    }
                    physics Physics {
                      density -1
                      mass 4.152
                      centerOfMass [
                        0.00746 -0.02346 -0.08193
                      ]
                      inertiaMatrix [
                        0.082618 0.081579 0.0060081
                        0 0 0
                      ]
                    }
                  }
                }
              ]
              name "left_hip_roll_link"
              boundingObject Cylinder {
                height 0.01
                radius 0.02
              }
              physics Physics {
                density -1
                mass 2.232
                centerOfMass [
                  -0.0058 -0.00319 -9e-05
                ]
                inertiaMatrix [
                  0.0020603 0.0022482 0.0024323
                  0 0 0
                ]
              }
            }
          }
        ]
        name "left_hip_yaw_link"
        boundingObject Cylinder {
          height 0.02
          radius 0.01
        }
        physics Physics {
          density -1
          mass 2.244
          centerOfMass [
            -0.04923 0.0001 0.0072
          ]
          inertiaMatrix [
            0.0025731 0.0030444 0.0022883
            0 0 0
          ]
        }
      }
    }
    HingeJoint {
      jointParameters HingeJointParameters {
        position 1.7952160451959132e-07
        axis 0 0 1
        anchor 0 -0.0875 -0.1742
      }
      device [
        RotationalMotor {
          name "right_hip_yaw_joint"
          maxVelocity 23
          minPosition -0.43
          maxPosition 0.43
          maxTorque 220
        }
        PositionSensor {
          name "right_hip_yaw_joint_sensor"
        }
      ]
      endPoint Solid {
        translation -1.1102239041022807e-16 -0.08749999999999947 -0.17419999999999947
        rotation 0 0 1 1.7881393432617193e-07
        children [
          DEF right_hip_yaw_link_visual CadShape {
            url [
              "../meshes/right_hip_yaw_link.dae"
            ]
          }
          HingeJoint {
            jointParameters HingeJointParameters {
              position -3.3209437411712116e-06
              anchor 0.039468 0 0
            }
            device [
              RotationalMotor {
                name "right_hip_roll_joint"
                maxVelocity 23
                minPosition -0.43
                maxPosition 0.43
                maxTorque 220
              }
              PositionSensor {
                name "right_hip_roll_joint_sensor"
              }
            ]
            endPoint Solid {
              translation 0.03946800000000001 2.7753363422556154e-17 -6.661339069462162e-16
              rotation -1 0 0 3.32092026965704e-06
              children [
                DEF right_hip_roll_link_visual CadShape {
                  url [
                    "../meshes/right_hip_roll_link.dae"
                  ]
                }
                HingeJoint {
                  jointParameters HingeJointParameters {
                    position -0.2999992694536777
                    axis 0 1 0
                    anchor 0 -0.11536 0
                  }
                  device [
                    RotationalMotor {
                      name "right_hip_pitch_joint"
                      maxVelocity 23
                      minPosition -3.14
                      maxPosition 2.53
                      maxTorque 220
                    }
                    PositionSensor {
                      name "right_hip_pitch_joint_sensor"
                    }
                  ]
                  endPoint Solid {
                    translation -5.551110676214764e-16 -0.11535999999999635 6.661341853507257e-16
                    rotation 0 -1 0 0.29999926945367816
                    children [
                      DEF right_hip_pitch_link_visual CadShape {
                        url [
                          "../meshes/right_hip_pitch_link.dae"
                        ]
                      }
                      HingeJoint {
                        jointParameters HingeJointParameters {
                          position 0.8000323099754538
                          axis 0 1 0
                          anchor 0 0 -0.4
                        }
                        device [
                          RotationalMotor {
                            name "right_knee_joint"
                            maxVelocity 14
                            minPosition -0.26
                            maxPosition 2.05
                            maxTorque 360
                          }
                          PositionSensor {
                            name "right_knee_joint_sensor"
                          }
                        ]
                        endPoint Solid {
                          translation 3.0438959931145e-17 -3.5527136788004997e-15 -0.40000000000000013
                          rotation 0 0.9999999999999999 0 0.8000323099754538
                          children [
                            DEF right_knee_link_visual CadShape {
                              url [
                                "../meshes/right_knee_link.dae"
                              ]
                            }
                            HingeJoint {
                              jointParameters HingeJointParameters {
                                position -0.46109964102307793
                                axis 0 1 0
                                anchor 0 0 -0.4
                              }
                              device [
                                RotationalMotor {
                                  name "right_ankle_joint"
                                  maxVelocity 9
                                  minPosition -0.87
                                  maxPosition 0.52
                                  maxTorque 45
                                }
                                PositionSensor {
                                  name "right_ankle_joint_sensor"
                                }
                              ]
                              endPoint DEF RightFootSole Solid {
                                translation 0.07202194928446726 1.7763568394003234e-15 -0.41992081377019497
                                rotation 0 -1 0 0.4610996410230775
                                children [
                                  TouchSensor {
                                    translation -7.673180424383474e-09 1.0593998567287599e-08 4.111136320678055e-07
                                    rotation -0.16357115216700027 0.9864595363259576 -0.01191895005178398 9.819825879962857e-09
                                    name "right_foot_sole_touch_sensor_3d"
                                    boundingObject Box {
                                      size 0.28 0.03 0.024
                                    }
                                    physics Physics {
                                      density -1
                                      mass 0.001
                                      centerOfMass [
                                        0 0 0
                                      ]
                                      inertiaMatrix [
                                        1.23e-06 6.581333333333335e-05 6.608333333333334e-05
                                        0 0 0
                                      ]
                                    }
                                    type "force-3d"
                                  }
                                  DEF right_ankle_torque_sensor HingeJoint {
                                    jointParameters HingeJointParameters {
                                      axis 0 1 0
                                    }
                                    device [
                                      RotationalMotor {
                                        name "right_ankle_torque_sensor_pitch"
                                      }
                                    ]
                                    endPoint Solid {
                                      rotation 0 1 0 0
                                      children [
                                        Solid {
                                          children [
                                            Shape {
                                              appearance Appearance {
                                                material Material {
                                                  diffuseColor 0.8 0.129412 0.6
                                                }
                                              }
                                              geometry Box {
                                                size 0.001 0.001 0.001
                                              }
                                            }
                                          ]
                                        }
                                      ]
                                    }
                                  }
                                  Pose {
                                    translation -0.046 0 0.056
                                    children [
                                      DEF right_ankle_link_visual CadShape {
                                        url [
                                          "../meshes/right_ankle_link.dae"
                                        ]
                                      }
                                    ]
                                  }
                                ]
                                name "right_ankle_link"
                                boundingObject Box {
                                  size 0.28 0.03 0.024
                                }
                                physics Physics {
                                  density -1
                                  mass 0.474
                                  centerOfMass [
                                    0.042575 1e-06 -0.044672
                                  ]
                                  inertiaMatrix [
                                    0.000159668 0.002900286 0.002805438
                                    0 0 0
                                  ]
                                }
                              }
                            }
                          ]
                          name "right_knee_link"
                          boundingObject Cylinder {
                            height 0.2
                            radius 0.05
                          }
                          physics Physics {
                            density -1
                            mass 1.721
                            centerOfMass [
                              -0.00136 0.00512 -0.1384
                            ]
                            inertiaMatrix [
                              0.012205 0.012509 0.0020629
                              0 0 0
                            ]
                          }
                        }
                      }
                    ]
                    name "right_hip_pitch_link"
                    boundingObject Cylinder {
                      height 0.2
                      radius 0.05
                    }
                    physics Physics {
                      density -1
                      mass 4.152
                      centerOfMass [
                        0.00746 0.02346 -0.08193
                      ]
                      inertiaMatrix [
                        0.082618 0.081579 0.0060081
                        0 0 0
                      ]
                    }
                  }
                }
              ]
              name "right_hip_roll_link"
              boundingObject Cylinder {
                height 0.01
                radius 0.02
              }
              physics Physics {
                density -1
                mass 2.232
                centerOfMass [
                  -0.0058 0.00319 -9e-05
                ]
                inertiaMatrix [
                  0.0020603 0.0022482 0.0024323
                  0 0 0
                ]
              }
            }
          }
        ]
        name "right_hip_yaw_link"
        boundingObject Cylinder {
          height 0.02
          radius 0.01
        }
        physics Physics {
          density -1
          mass 2.244
          centerOfMass [
            -0.04923 -0.0001 0.0072
          ]
          inertiaMatrix [
            0.0025731 0.0030444 0.0022883
            0 0 0
          ]
        }
      }
    }
    HingeJoint {
      jointParameters HingeJointParameters {
        position 1.1524356891490635e-08
        axis 0 0 1
      }
      device [
        RotationalMotor {
          name "torso_joint"
          maxVelocity 23
          minPosition -2.35
          maxPosition 2.35
          maxTorque 200
        }
        PositionSensor {
          name "torso_joint_sensor"
        }
      ]
      endPoint Solid {
        translation -4.666503617894528e-05 6.134766262237026e-05 -0.001146357235751073
        rotation -0.9186807399533578 0.38551464276810943 0.08604741861396939 0.0001223818353197323
        children [
          DEF torso_link_visual CadShape {
            url [
              "../meshes/torso_link.dae"
            ]
          }
          HingeJoint {
            jointParameters HingeJointParameters {
              position -6.735231141567647e-07
              axis 0 0.906309 0.422616
              anchor 0.0055 0.15535 0.42999
            }
            device [
              RotationalMotor {
                name "left_shoulder_pitch_joint"
                maxVelocity 9
                minPosition -2.87
                maxPosition 2.87
                maxTorque 75
              }
              PositionSensor {
                name "left_shoulder_pitch_joint_sensor"
              }
            ]
            endPoint Solid {
              translation 0.005500000000000171 0.15535000000000299 0.42999000000000054
              rotation 0.9999999999987619 -1.5362082556641107e-06 -3.405669054501388e-07 0.4363300000004493
              children [
                DEF left_shoulder_pitch_link_visual CadShape {
                  url [
                    "../meshes/left_shoulder_pitch_link.dae"
                  ]
                }
                HingeJoint {
                  jointParameters HingeJointParameters {
                    position 0.007754557447942341
                    anchor -0.0055 0.0565 -0.0165
                  }
                  device [
                    RotationalMotor {
                      name "left_shoulder_roll_joint"
                      maxVelocity 9
                      minPosition -0.34
                      maxPosition 3.11
                      maxTorque 75
                    }
                    PositionSensor {
                      name "left_shoulder_roll_joint_sensor"
                    }
                  ]
                  endPoint Solid {
                    translation -0.0055000000000002824 0.05649999999999977 -0.01649999999999974
                    rotation -1 -7.121826903359115e-18 -4.1562276883616924e-18 0.4285755714431088
                    children [
                      DEF left_shoulder_roll_link_visual CadShape {
                        url [
                          "../meshes/left_shoulder_roll_link.dae"
                        ]
                      }
                      HingeJoint {
                        jointParameters HingeJointParameters {
                          position 2.6132273958533486e-06
                          axis 0 0 1
                          anchor 0 0 -0.1343
                        }
                        device [
                          RotationalMotor {
                            name "left_shoulder_yaw_joint"
                            maxVelocity 20
                            minPosition -1.3
                            maxPosition 4.45
                            maxTorque 75
                          }
                          PositionSensor {
                            name "left_shoulder_yaw_joint_sensor"
                          }
                        ]
                        endPoint Solid {
                          translation 3.3306925577103525e-16 -8.881775390527687e-16 -0.1342999999999992
                          rotation 0 0 1 2.613274549119406e-06
                          children [
                            DEF left_shoulder_yaw_link_visual CadShape {
                              url [
                                "../meshes/left_shoulder_yaw_link.dae"
                              ]
                            }
                            HingeJoint {
                              jointParameters HingeJointParameters {
                                position 3.863222783873184e-05
                                axis 0 1 0
                                anchor 0.0185 0 -0.198
                              }
                              device [
                                RotationalMotor {
                                  name "left_elbow_joint"
                                  maxVelocity 20
                                  minPosition -1.8
                                  maxPosition 3
                                  maxTorque 75
                                }
                                PositionSensor {
                                  name "left_elbow_joint_sensor"
                                }
                              ]
                              endPoint Solid {
                                translation 0.018499999964552347 -1.4921397450961867e-13 -0.19800000088529532
                                rotation 0 1 0 3.863222529485805e-05
                                children [
                                  TouchSensor {
                                    translation 0.2700000054800087 5.378999645699878e-08 -0.02000002765310893
                                    rotation -0.12696109168603983 0.9188364730866133 0.3736581551681189 8.325792159410242e-10
                                    children [
                                      DEF Cone Pose {
                                        translation 0 -0.024 0
                                        rotation 1 0 0 -1.5707953071795862
                                        children [
                                          Shape {
                                            appearance Cardboard {
                                              type "front"
                                            }
                                            geometry Cone {
                                              bottomRadius 0.095
                                              height 0.05
                                            }
                                          }
                                        ]
                                      }
                                      Pose {
                                        translation 0 -0.045 0
                                        rotation 1 0 0 1.57
                                        children [
                                          Solid {
                                            children [
                                              DEF CIRCLE_EE TorusBoundingObject {
                                                majorRadius 0.06
                                                minorRadius 0.01
                                                subdivision 43
                                              }
                                            ]
                                            boundingObject USE CIRCLE_EE
                                            physics Physics {
                                              density -1
                                              mass 0.001
                                            }
                                          }
                                        ]
                                      }
                                      DEF WRIST_TOUCH_SENSOR Shape {
                                        appearance PBRAppearance {
                                          baseColor 0 0 0
                                          roughness 1
                                          metalness 0
                                        }
                                        geometry Sphere {
                                          radius 0.04
                                        }
                                      }
                                    ]
                                    name "left_wrist_touch_sensor_3d"
                                    boundingObject USE WRIST_TOUCH_SENSOR
                                    physics Physics {
                                      density 1
                                    }
                                    type "force-3d"
                                  }
                                  DEF left_elbow_link_visual CadShape {
                                    url [
                                      "../meshes/left_elbow_link.dae"
                                    ]
                                  }
                                ]
                                name "left_elbow_link"
                                boundingObject Cylinder {
                                  height 0.09
                                  radius 0.03
                                }
                                physics Physics {
                                  density -1
                                  mass 0.723
                                  centerOfMass [
                                    0.164862 0.000118 -0.015734
                                  ]
                                  inertiaMatrix [
                                    0.00042388 0.0060062 0.0060023
                                    0 0 0
                                  ]
                                }
                              }
                            }
                          ]
                          name "left_shoulder_yaw_link"
                          boundingObject Cylinder {
                            height 0.01
                            radius 0.04
                          }
                          physics Physics {
                            density -1
                            mass 0.839
                            centerOfMass [
                              0.01365 0.002767 -0.16266
                            ]
                            inertiaMatrix [
                              0.003664 0.0040789 0.00066383
                              0 0 0
                            ]
                          }
                        }
                      }
                    ]
                    name "left_shoulder_roll_link"
                    boundingObject Cylinder {
                      height 0.01
                      radius 0.04
                    }
                    physics Physics {
                      density -1
                      mass 0.793
                      centerOfMass [
                        0.000679 0.00115 -0.094076
                      ]
                      inertiaMatrix [
                        0.0015742 0.0016973 0.0010183
                        0 0 0
                      ]
                    }
                  }
                }
              ]
              name "left_shoulder_pitch_link"
              boundingObject Cylinder {
                height 0.04
                radius 0.03
              }
              physics Physics {
                density -1
                mass 1.033
                centerOfMass [
                  0.005045 0.053657 -0.015715
                ]
                inertiaMatrix [
                  0.0012985 0.00087279 0.00097338
                  0 0 0
                ]
              }
            }
          }
          HingeJoint {
            jointParameters HingeJointParameters {
              position 6.730432224379688e-06
              axis 0 0.906309 -0.422616
              anchor 0.0055 -0.15535 0.42999
            }
            device [
              RotationalMotor {
                name "right_shoulder_pitch_joint"
                maxVelocity 9
                minPosition -2.87
                maxPosition 2.87
                maxTorque 75
              }
              PositionSensor {
                name "right_shoulder_pitch_joint_sensor"
              }
            ]
            endPoint Solid {
              translation 0.005499999999999949 -0.15534999999999766 0.4299900000000001
              rotation -0.9999999998794009 1.5162425598508875e-05 -3.361406465561619e-06 0.4363300000508847
              children [
                DEF right_shoulder_pitch_link_visual CadShape {
                  url [
                    "../meshes/right_shoulder_pitch_link.dae"
                  ]
                }
                HingeJoint {
                  jointParameters HingeJointParameters {
                    position -0.0005360280351749785
                    anchor -0.0055 -0.0565 -0.0165
                  }
                  device [
                    RotationalMotor {
                      name "right_shoulder_roll_joint"
                      maxVelocity 9
                      minPosition -3.11
                      maxPosition 0.34
                      maxTorque 75
                    }
                    PositionSensor {
                      name "right_shoulder_roll_joint_sensor"
                    }
                  ]
                  endPoint Solid {
                    translation -0.005499999999999838 -0.05649999999999977 -0.01649999999999929
                    rotation 0.9999999999999999 -2.5575927119304097e-17 8.742570638930904e-18 0.4357941526263651
                    children [
                      DEF right_shoulder_roll_link_visual CadShape {
                        url [
                          "../meshes/right_shoulder_roll_link.dae"
                        ]
                      }
                      HingeJoint {
                        jointParameters HingeJointParameters {
                          position -5.284535960145457e-06
                          axis 0 0 1
                          anchor 0 0 -0.1343
                        }
                        device [
                          RotationalMotor {
                            name "right_shoulder_yaw_joint"
                            maxVelocity 20
                            minPosition -4.45
                            maxPosition 1.3
                            maxTorque 75
                          }
                          PositionSensor {
                            name "right_shoulder_yaw_joint_sensor"
                          }
                        ]
                        endPoint Solid {
                          translation 1.1102230246095185e-16 -5.902033865464208e-22 -0.13430000000000097
                          rotation 0 0 -1 5.284515670544235e-06
                          children [
                            DEF right_shoulder_yaw_link_visual CadShape {
                              url [
                                "../meshes/right_shoulder_yaw_link.dae"
                              ]
                            }
                            HingeJoint {
                              jointParameters HingeJointParameters {
                                position 4.225882948271529e-05
                                axis 0 1 0
                                anchor 0.0185 0 -0.198
                              }
                              device [
                                RotationalMotor {
                                  name "right_elbow_joint"
                                  maxVelocity 20
                                  minPosition -2.5
                                  maxPosition 2.61
                                  maxTorque 75
                                }
                                PositionSensor {
                                  name "right_elbow_joint_sensor"
                                }
                              ]
                              endPoint Solid {
                                translation 0.018499999890113788 -4.67181848762261e-13 -0.19800000274411048
                                rotation 0 0.9999999999999999 0 4.2258831434495905e-05
                                children [
                                  TouchSensor {
                                    translation 0.2699999923683549 -5.3992157411641983e-08 -0.020000029967134347
                                    rotation -0.05306507312403008 0.2976736147538501 0.9531917525313139 1.873848534852673e-09
                                    children [
                                      DEF Cone Pose {
                                        translation 0 0.02 0
                                        rotation -1 0 0 -1.5707953071795862
                                        children [
                                          Shape {
                                            appearance Cardboard {
                                              type "front"
                                            }
                                            geometry Cone {
                                              bottomRadius 0.088
                                              height 0.06
                                            }
                                          }
                                        ]
                                      }
                                      Pose {
                                        translation 0 0.045 0
                                        rotation 1 0 0 1.57
                                        children [
                                          Solid {
                                            children [
                                              TorusBoundingObject {
                                                majorRadius 0.06
                                                minorRadius 0.01
                                                subdivision 43
                                              }
                                            ]
                                            boundingObject USE CIRCLE_EE
                                            physics Physics {
                                              mass 0.001
                                            }
                                          }
                                        ]
                                      }
                                      DEF WRIST_TOUCH_SENSOR Shape {
                                        appearance PBRAppearance {
                                          baseColor 0 0 0
                                          roughness 1
                                          metalness 0
                                        }
                                        geometry Sphere {
                                          radius 0.04
                                        }
                                      }
                                    ]
                                    name "right_wrist_touch_sensor_3d"
                                    boundingObject USE WRIST_TOUCH_SENSOR
                                    physics Physics {
                                      density 1
                                    }
                                    type "force-3d"
                                  }
                                  DEF right_elbow_link_visual CadShape {
                                    url [
                                      "../meshes/right_elbow_link.dae"
                                    ]
                                  }
                                ]
                                name "right_elbow_link"
                                boundingObject Cylinder {
                                  height 0.09
                                  radius 0.03
                                }
                                physics Physics {
                                  density -1
                                  mass 0.723
                                  centerOfMass [
                                    0.164862 -0.000118 -0.015734
                                  ]
                                  inertiaMatrix [
                                    0.00042388 0.0060062 0.0060023
                                    0 0 0
                                  ]
                                }
                              }
                            }
                          ]
                          name "right_shoulder_yaw_link"
                          boundingObject Cylinder {
                            height 0.01
                            radius 0.04
                          }
                          physics Physics {
                            density -1
                            mass 0.839
                            centerOfMass [
                              0.01365 -0.002767 -0.16266
                            ]
                            inertiaMatrix [
                              0.003664 0.0040789 0.00066383
                              0 0 0
                            ]
                          }
                        }
                      }
                    ]
                    name "right_shoulder_roll_link"
                    boundingObject Cylinder {
                      height 0.01
                      radius 0.04
                    }
                    physics Physics {
                      density -1
                      mass 0.793
                      centerOfMass [
                        0.000679 -0.00115 -0.094076
                      ]
                      inertiaMatrix [
                        0.0015742 0.0016973 0.0010183
                        0 0 0
                      ]
                    }
                  }
                }
              ]
              name "right_shoulder_pitch_link"
              boundingObject Cylinder {
                height 0.04
                radius 0.03
              }
              physics Physics {
                density -1
                mass 1.033
                centerOfMass [
                  0.005045 -0.053657 -0.015715
                ]
                inertiaMatrix [
                  0.0012985 0.00087279 0.00097338
                  0 0 0
                ]
              }
            }
          }
          Solid {
            translation 0.108485 0.0175 0.693171
            rotation -0.6856987715190361 0.6857007715183697 -0.2441959186317357 2.662578
            children [
              Shape {
                appearance DEF d435_left_imager_link_material PBRAppearance {
                  roughness 1
                  metalness 0
                }
                geometry Sphere {
                  radius 0.001
                }
              }
            ]
            name "d435_left_imager_link"
            boundingObject Sphere {
              radius 0.001
            }
            physics Physics {
            }
          }
          Solid {
            translation 0.108485 0.0325 0.693171
            rotation -0.6856987715190361 0.6857007715183697 -0.2441959186317357 2.662578
            children [
              Shape {
                appearance DEF d435_rgb_module_link_material PBRAppearance {
                  roughness 1
                  metalness 0
                }
                geometry Sphere {
                  radius 0.001
                }
              }
            ]
            name "d435_rgb_module_link"
            boundingObject Sphere {
              radius 0.001
            }
            physics Physics {
            }
          }
          Solid {
            translation 0.0473 0 0.674929
            rotation 0 1 0 0.243124
            children [
              Shape {
                appearance DEF mid360_link_material PBRAppearance {
                  roughness 1
                  metalness 0
                }
                geometry Sphere {
                  radius 0.001
                }
              }
            ]
            name "mid360_link"
            boundingObject Sphere {
              radius 0.001
            }
            physics Physics {
            }
          }
        ]
        name "torso_link"
        boundingObject Box {
          size 0.08 0.16 0.1
        }
        physics Physics {
          density -1
          mass 17.789
          centerOfMass [
            0.000489 0.002797 0.20484
          ]
          inertiaMatrix [
            0.4873 0.40963 0.12785
            0 0 0
          ]
        }
      }
    }
  ]
  name "UnitreeH1"
  boundingObject Sphere {
    radius 0.05
  }
  physics Physics {
    density -1
    mass 5.39
    centerOfMass [
      -0.0002 4e-05 -0.04522
    ]
    inertiaMatrix [
      0.044582 0.0082464 0.049021
      0 0 0
    ]
  }
  controller "<extern>"
  supervisor TRUE
}
Solid {
  translation -0.6639818937306741 -5.062522129934739 0.9462713697856847
  rotation -0.16798386173004212 -0.8526517594722273 0.49473871818079634 0.007686854961454494
  children [
    Pose {
      children [
        DEF LeftHand Solid {
          translation 0 -0.136 0.11
          rotation 1 0 0 1.5708
          children [
            Shape {
              appearance Cardboard {
                type "front"
              }
              geometry DEF BOX_HAND Cylinder {
                height 0.063
                radius 0.04
              }
            }
          ]
          name "BoxHand1"
          boundingObject USE BOX_HAND
          physics Physics {
            density -1
            mass 0.01
          }
        }
      ]
    }
    Pose {
      children [
        DEF RightHand Solid {
          translation 0 0.141 0.11
          rotation 1 0 0 1.5708
          children [
            Shape {
              appearance Cardboard {
                type "front"
              }
              geometry DEF BOX_HAND Cylinder {
                height 0.07
                radius 0.04
              }
            }
          ]
          name "BoxHand2"
          boundingObject USE BOX_HAND
          physics Physics {
            mass 0.01
          }
        }
      ]
    }
    Shape {
      appearance Cardboard {
        type "front"
      }
      geometry DEF CARRY_BOX Box {
        size 0.25 0.23 0.35
      }
    }
  ]
  name "CarryBox"
  boundingObject USE CARRY_BOX
  physics Physics {
    density -1
    mass 10
  }
}
Robot {
  translation -23.16085691362866 12.964847567168421 0.08788473715218884
  rotation -0.6647222039902301 -0.6572973875568654 0.35511200463134324 0.00044135503295173687
  children [
    Solid {
      translation 18.8 -21.56 0
      children [
        Pose {
          children [
            DEF VERTICAL_PILLAR Solid {
              translation 0 -1.69826e-06 0.92
              rotation -1 0 0 -5.307179586466759e-06
              children [
                DEF HORIZENTAL_PILLAR Solid {
                  translation 0 0.97 0.990001
                  rotation 1 0 0 1.5708
                  children [
                    HingeJoint {
                      jointParameters HingeJointParameters {
                        position -5.438648675154052e-10
                        axis 0 0 1
                        anchor -8.04912e-15 0 -1
                      }
                      device [
                        RotationalMotor {
                        }
                      ]
                      endPoint DEF HORIZENTAL_PILLAR Solid {
                        translation -5.800665831837064e-09 -0.5000000000122481 -1.0000000000474467
                        rotation 1 -5.705759690526569e-09 -5.895536887666923e-09 1.570800000094885
                        children [
                          Shape {
                            appearance Cardboard {
                              type "front"
                            }
                            geometry DEF BOX_HAND Cylinder {
                              height 1
                              radius 0.04
                            }
                          }
                        ]
                        name "PILLAR"
                        boundingObject USE BOX_HAND
                        physics Physics {
                          density -1
                          mass 10
                        }
                      }
                    }
                    Shape {
                      appearance Cardboard {
                        type "front"
                      }
                      geometry DEF BOX_HAND Cylinder {
                        radius 0.04
                      }
                    }
                  ]
                  name "PILLAR"
                  boundingObject USE BOX_HAND
                  physics Physics {
                    density -1
                    mass 0.01
                  }
                }
                Shape {
                  appearance Cardboard {
                    type "front"
                  }
                  geometry DEF BOX_HAND Cylinder {
                    radius 0.04
                  }
                }
              ]
              name "PILLAR"
              boundingObject USE BOX_HAND
              physics Physics {
                density -1
                mass 0.01
              }
            }
          ]
        }
        Shape {
          appearance Cardboard {
            type "front"
          }
          geometry DEF PENDULUM Box {
            size 1.5 1.5 0.2
          }
        }
      ]
      name "Pendulem"
      boundingObject USE PENDULUM
      physics Physics {
        density -1
        mass 0.001
      }
    }
  ]
  boundingObject USE PENDULUM
  physics Physics {
    density -1
    mass 10000
  }
}
