#VRML_SIM R2023b utf8

EXTERNPROTO "https://raw.githubusercontent.com/cyberbotics/webots/R2023b/projects/objects/backgrounds/protos/TexturedBackground.proto"
EXTERNPROTO "https://raw.githubusercontent.com/cyberbotics/webots/R2023b/projects/objects/backgrounds/protos/TexturedBackgroundLight.proto"
EXTERNPROTO "https://raw.githubusercontent.com/cyberbotics/webots/R2023b/projects/objects/floors/protos/RectangleArena.proto"
EXTERNPROTO "https://raw.githubusercontent.com/cyberbotics/webots/R2023b/projects/objects/advertising_board/protos/AdvertisingBoard.proto"
EXTERNPROTO "https://raw.githubusercontent.com/cyberbotics/webots/R2023b/projects/appearances/protos/Cardboard.proto"
EXTERNPROTO "https://raw.githubusercontent.com/cyberbotics/webots/R2023b/projects/bounding_objects/protos/TorusBoundingObject.proto"
EXTERNPROTO "https://raw.githubusercontent.com/cyberbotics/webots/R2023b/projects/appearances/protos/Parquetry.proto"

WorldInfo {
  gravity 9.8
  CFM 1e-07
  ERP 0.8
  basicTimeStep 1
  FPS 30
  optimalThreadCount 8
  contactProperties [
    ContactProperties {
      coulombFriction [
        0.9
      ]
      bounce 0.3
      bounceVelocity 0.003
      softERP 0.42
      softCFM 0.000208
    }
  ]
}
Viewpoint {
  orientation 0.4131476080303487 0.0773175373715682 -0.9073759157006522 2.8051795249850673
  position 2.404858172631083 -3.156775908934534 4.785348421788611
}
TexturedBackground {
}
TexturedBackgroundLight {
  luminosity 0.8
}
RectangleArena {
  translation -0.246845 -3.09843 4.44089e-16
  rotation 0 0 -1 0
  floorSize 50 50
  floorAppearance Parquetry {
    type "light strip"
    colorOverride 0.682353 0.670588 0.662745
  }
}
TexturedBackgroundLight {
  luminosity 0.2
}
AdvertisingBoard {
  translation -1.29955 -6.20696 -4.9738e-14
  rotation 0 0 -1 1.5708
  recognitionColors [
    1 0.847059 0.933333
    0.74902 0.737255 0.741176
  ]
  displayWidth 7
  frameColor 0.666667 0.666667 0.498039
  poleColor 0.862745 0.886275 0.717647
  baseRatio 3
}
DEF UnitreeH1 Robot {
  translation -0.9512248512511752 -5.057007548467772 0.9699302867014086
  rotation 0.008365537523432854 -0.9976387380255948 0.06816865975389778 0.040121309302556966
  children [
    GPS {
      name "gps_upperBody"
    }
    InertialUnit {
      name "inertial_unit_upperBody"
    }
    Gyro {
      name "gyro_upperBody"
    }
    Accelerometer {
      name "accelerometer_upperBody"
    }
    DEF pelvis_visual CadShape {
      url [
        "../meshes/pelvis.dae"
      ]
    }
    HingeJoint {
      jointParameters HingeJointParameters {
        position -1.0866181499655638e-08
        axis 0 0 1
        anchor 0 0.0875 -0.1742
      }
      device [
        RotationalMotor {
          name "left_hip_yaw_joint"
          maxVelocity 23
          minPosition -0.43
          maxPosition 0.43
          maxTorque 220
        }
        PositionSensor {
          name "left_hip_yaw_joint_sensor"
        }
      ]
      endPoint Solid {
        translation 1.1102230372472656e-16 0.08750000000000036 -0.17419999999999947
        children [
          DEF left_hip_yaw_link_visual CadShape {
            url [
              "../meshes/left_hip_yaw_link.dae"
            ]
          }
          HingeJoint {
            jointParameters HingeJointParameters {
              position 1.8084666514003086e-07
              anchor 0.039468 0 0
            }
            device [
              RotationalMotor {
                name "left_hip_roll_joint"
                maxVelocity 23
                minPosition -0.43
                maxPosition 0.43
                maxTorque 220
              }
              PositionSensor {
                name "left_hip_roll_joint_sensor"
              }
            ]
            endPoint Solid {
              translation 0.039467999999999975 5.55112716993354e-17 -6.661338047360742e-16
              rotation 0.9999999999999999 0 0 1.812804499357409e-07
              children [
                DEF left_hip_roll_link_visual CadShape {
                  url [
                    "../meshes/left_hip_roll_link.dae"
                  ]
                }
                HingeJoint {
                  jointParameters HingeJointParameters {
                    position -0.2999999123393692
                    axis 0 1 0
                    anchor 0 0.11536 0
                  }
                  device [
                    RotationalMotor {
                      name "left_hip_pitch_joint"
                      maxVelocity 23
                      minPosition -3.14
                      maxPosition 2.53
                      maxTorque 220
                    }
                    PositionSensor {
                      name "left_hip_pitch_joint_sensor"
                    }
                  ]
                  endPoint Solid {
                    translation 5.551115180796401e-16 0.1153600000000008 2.220445905073636e-16
                    rotation 0 -1 0 0.2999999123393688
                    children [
                      DEF left_hip_pitch_link_visual CadShape {
                        url [
                          "../meshes/left_hip_pitch_link.dae"
                        ]
                      }
                      HingeJoint {
                        jointParameters HingeJointParameters {
                          position 0.8000003880092639
                          axis 0 1 0
                          anchor 0 0 -0.4
                        }
                        device [
                          RotationalMotor {
                            name "left_knee_joint"
                            maxVelocity 14
                            minPosition -0.26
                            maxPosition 2.05
                            maxTorque 360
                          }
                          PositionSensor {
                            name "left_knee_joint_sensor"
                          }
                        ]
                        endPoint Solid {
                          translation -2.1821781893256487e-16 0 -0.40000000000000036
                          rotation 0 0.9999999999999999 0 0.8000003880092639
                          children [
                            DEF left_knee_link_visual CadShape {
                              url [
                                "../meshes/left_knee_link.dae"
                              ]
                            }
                            HingeJoint {
                              jointParameters HingeJointParameters {
                                position -0.46000005490372975
                                axis 0 1 0
                                anchor 0 0 -0.4
                              }
                              device [
                                RotationalMotor {
                                  name "left_ankle_joint"
                                  maxVelocity 9
                                  minPosition -0.9000211187369112
                                  maxPosition 0.52
                                  maxTorque 45
                                }
                                PositionSensor {
                                  name "left_ankle_joint_sensor"
                                }
                              ]
                              endPoint DEF LeftFootSole Solid {
                                translation 0.07201792531530724 -1.776356839400253e-15 -0.4201191061749392
                                rotation 0 -1 0 0.4600000549037296
                                children [
                                  TouchSensor {
                                    translation 6.992266432526151e-09 -8.241251236995595e-09 3.052136428056268e-07
                                    rotation -0.19633855225379274 0.9632473388325511 0.18331867643776298 7.071144892251375e-09
                                    name "left_foot_sole_touch_sensor_3d"
                                    boundingObject Box {
                                      size 0.28 0.03 0.024
                                    }
                                    physics Physics {
                                      density -1
                                      mass 0.001
                                      centerOfMass [
                                        0 0 0
                                      ]
                                      inertiaMatrix [
                                        1.23e-06 6.581333333333335e-05 6.608333333333334e-05
                                        0 0 0
                                      ]
                                    }
                                    type "force-3d"
                                    linearVelocity 4.794127497764755e-09 6.231417382096538e-08 7.125218817738421e-12
                                    angularVelocity 7.626384259599821e-08 -2.317055741400619e-08 5.793983434773774e-08
                                  }
                                  DEF left_ankle_torque_sensor HingeJoint {
                                    jointParameters HingeJointParameters {
                                      axis 0 1 0
                                    }
                                    device [
                                      RotationalMotor {
                                        name "left_ankle_torque_sensor_pitch"
                                      }
                                    ]
                                    endPoint Solid {
                                      rotation 0 1 0 0
                                      children [
                                        Solid {
                                          children [
                                            Shape {
                                              appearance Appearance {
                                                material Material {
                                                  diffuseColor 0.8 0.129412 0.6
                                                }
                                              }
                                              geometry Box {
                                                size 0.001 0.001 0.001
                                              }
                                            }
                                          ]
                                        }
                                      ]
                                    }
                                  }
                                  Pose {
                                    translation -0.046 0 0.056
                                    children [
                                      DEF left_ankle_link_visual CadShape {
                                        url [
                                          "../meshes/left_ankle_link.dae"
                                        ]
                                      }
                                    ]
                                  }
                                ]
                                name "left_ankle_link"
                                boundingObject Box {
                                  size 0.28 0.03 0.024
                                }
                                physics Physics {
                                  density -1
                                  mass 0.474
                                  centerOfMass [
                                    0.042575 -1e-06 -0.044672
                                  ]
                                  inertiaMatrix [
                                    0.000159668 0.002900286 0.002805438
                                    0 0 0
                                  ]
                                }
                                linearVelocity 5.74258322634829e-09 6.771096429534205e-08 1.0032928638215526e-09
                                angularVelocity 7.625858691897422e-08 -2.3170079439853126e-08 5.7922949310459256e-08
                              }
                            }
                          ]
                          name "left_knee_link"
                          boundingObject Cylinder {
                            height 0.2
                            radius 0.05
                          }
                          physics Physics {
                            density -1
                            mass 1.721
                            centerOfMass [
                              -0.00136 -0.00512 -0.1384
                            ]
                            inertiaMatrix [
                              0.012205 0.012509 0.0020629
                              0 0 0
                            ]
                          }
                          linearVelocity -1.5131693980888838e-09 4.259740473752228e-08 8.797314930522657e-10
                          angularVelocity 7.619707557798742e-08 -2.2143452678815305e-08 5.78367961860205e-08
                        }
                      }
                    ]
                    name "left_hip_pitch_link"
                    boundingObject Cylinder {
                      height 0.2
                      radius 0.05
                    }
                    physics Physics {
                      density -1
                      mass 4.152
                      centerOfMass [
                        0.00746 -0.02346 -0.08193
                      ]
                      inertiaMatrix [
                        0.082618 0.081579 0.0060081
                        0 0 0
                      ]
                    }
                    linearVelocity -7.726326737649646e-09 7.22502468232065e-09 -5.773812196924162e-10
                    angularVelocity 7.577799870401045e-08 -1.4549184450846504e-08 5.7920713835398563e-08
                  }
                }
              ]
              name "left_hip_roll_link"
              boundingObject Cylinder {
                height 0.01
                radius 0.02
              }
              physics Physics {
                density -1
                mass 2.232
                centerOfMass [
                  -0.0058 -0.00319 -9e-05
                ]
                inertiaMatrix [
                  0.0020603 0.0022482 0.0024323
                  0 0 0
                ]
              }
              linearVelocity -3.460580462302608e-09 -1.6706424457494033e-09 -8.199738469890172e-09
              angularVelocity 7.498274158810717e-08 -5.2013534565461333e-11 5.788018724653776e-08
            }
          }
        ]
        name "left_hip_yaw_link"
        boundingObject Cylinder {
          height 0.02
          radius 0.01
        }
        physics Physics {
          density -1
          mass 2.244
          centerOfMass [
            -0.04923 0.0001 0.0072
          ]
          inertiaMatrix [
            0.0025731 0.0030444 0.0022883
            0 0 0
          ]
        }
        linearVelocity -3.795662092469345e-09 -7.21741345560373e-09 -7.97025186816103e-09
        angularVelocity 4.0120378429985624e-09 -1.193746681551811e-10 5.504203370326633e-08
      }
    }
    HingeJoint {
      jointParameters HingeJointParameters {
        position 1.004300098076847e-08
        axis 0 0 1
        anchor 0 -0.0875 -0.1742
      }
      device [
        RotationalMotor {
          name "right_hip_yaw_joint"
          maxVelocity 23
          minPosition -0.43
          maxPosition 0.43
          maxTorque 220
        }
        PositionSensor {
          name "right_hip_yaw_joint_sensor"
        }
      ]
      endPoint Solid {
        translation -1.1102229046933128e-16 -0.08749999999999947 -0.17419999999999947
        children [
          DEF right_hip_yaw_link_visual CadShape {
            url [
              "../meshes/right_hip_yaw_link.dae"
            ]
          }
          HingeJoint {
            jointParameters HingeJointParameters {
              position -1.8650134054033166e-07
              anchor 0.039468 0 0
            }
            device [
              RotationalMotor {
                name "right_hip_roll_joint"
                maxVelocity 23
                minPosition -0.43
                maxPosition 0.43
                maxTorque 220
              }
              PositionSensor {
                name "right_hip_roll_joint_sensor"
              }
            ]
            endPoint Solid {
              translation 0.03946800000000001 2.775545138078182e-17 -6.661338199516106e-16
              rotation -1 0 0 1.8611544365878105e-07
              children [
                DEF right_hip_roll_link_visual CadShape {
                  url [
                    "../meshes/right_hip_roll_link.dae"
                  ]
                }
                HingeJoint {
                  jointParameters HingeJointParameters {
                    position -0.29999992050697577
                    axis 0 1 0
                    anchor 0 -0.11536 0
                  }
                  device [
                    RotationalMotor {
                      name "right_hip_pitch_joint"
                      maxVelocity 23
                      minPosition -3.14
                      maxPosition 2.53
                      maxTorque 220
                    }
                    PositionSensor {
                      name "right_hip_pitch_joint_sensor"
                    }
                  ]
                  endPoint Solid {
                    translation -5.551115013102376e-16 -0.11535999999999635 6.661338239437209e-16
                    rotation 0 -1 0 0.29999992050697616
                    children [
                      DEF right_hip_pitch_link_visual CadShape {
                        url [
                          "../meshes/right_hip_pitch_link.dae"
                        ]
                      }
                      HingeJoint {
                        jointParameters HingeJointParameters {
                          position 0.8000003684393614
                          axis 0 1 0
                          anchor 0 0 -0.4
                        }
                        device [
                          RotationalMotor {
                            name "right_knee_joint"
                            maxVelocity 14
                            minPosition -0.26
                            maxPosition 2.05
                            maxTorque 360
                          }
                          PositionSensor {
                            name "right_knee_joint_sensor"
                          }
                        ]
                        endPoint Solid {
                          translation 3.044591219325977e-17 -3.552713678800504e-15 -0.40000000000000013
                          rotation 0 1 0 0.8000003684393614
                          children [
                            DEF right_knee_link_visual CadShape {
                              url [
                                "../meshes/right_knee_link.dae"
                              ]
                            }
                            HingeJoint {
                              jointParameters HingeJointParameters {
                                position -0.4600000490114327
                                axis 0 1 0
                                anchor 0 0 -0.4
                              }
                              device [
                                RotationalMotor {
                                  name "right_ankle_joint"
                                  maxVelocity 9
                                  minPosition -0.87
                                  maxPosition 0.52
                                  maxTorque 45
                                }
                                PositionSensor {
                                  name "right_ankle_joint_sensor"
                                }
                              ]
                              endPoint DEF RightFootSole Solid {
                                translation 0.07200000098023371 1.7763568394002714e-15 -0.4199999964711789
                                rotation 0 -1 0 0.46000004901143243
                                children [
                                  TouchSensor {
                                    translation -8.167493237287715e-09 7.893445008733124e-09 2.918511559681092e-07
                                    rotation -0.17266268273523683 0.9788301084468479 0.10990549025687099 6.622701419031054e-09
                                    name "right_foot_sole_touch_sensor_3d"
                                    boundingObject Box {
                                      size 0.28 0.03 0.024
                                    }
                                    physics Physics {
                                      density -1
                                      mass 0.001
                                      centerOfMass [
                                        0 0 0
                                      ]
                                      inertiaMatrix [
                                        1.23e-06 6.581333333333335e-05 6.608333333333334e-05
                                        0 0 0
                                      ]
                                    }
                                    type "force-3d"
                                    linearVelocity -4.793658012203217e-09 -6.239522098994144e-08 -1.110730778186575e-11
                                    angularVelocity -6.947378616843191e-08 2.3182095538638024e-08 4.8712908544185473e-08
                                  }
                                  DEF right_ankle_torque_sensor HingeJoint {
                                    jointParameters HingeJointParameters {
                                      axis 0 1 0
                                    }
                                    device [
                                      RotationalMotor {
                                        name "right_ankle_torque_sensor_pitch"
                                      }
                                    ]
                                    endPoint Solid {
                                      rotation 0 1 0 0
                                      children [
                                        Solid {
                                          children [
                                            Shape {
                                              appearance Appearance {
                                                material Material {
                                                  diffuseColor 0.8 0.129412 0.6
                                                }
                                              }
                                              geometry Box {
                                                size 0.001 0.001 0.001
                                              }
                                            }
                                          ]
                                        }
                                      ]
                                    }
                                  }
                                  Pose {
                                    translation -0.046 0 0.056
                                    children [
                                      DEF right_ankle_link_visual CadShape {
                                        url [
                                          "../meshes/right_ankle_link.dae"
                                        ]
                                      }
                                    ]
                                  }
                                ]
                                name "right_ankle_link"
                                boundingObject Box {
                                  size 0.28 0.03 0.024
                                }
                                physics Physics {
                                  density -1
                                  mass 0.474
                                  centerOfMass [
                                    0.042575 1e-06 -0.044672
                                  ]
                                  inertiaMatrix [
                                    0.000159668 0.002900286 0.002805438
                                    0 0 0
                                  ]
                                }
                                linearVelocity -5.7564215861239236e-09 -6.294933981964181e-08 -1.0071603361627845e-09
                                angularVelocity -6.946813244132596e-08 2.318173295768308e-08 4.869739264449574e-08
                              }
                            }
                          ]
                          name "right_knee_link"
                          boundingObject Cylinder {
                            height 0.2
                            radius 0.05
                          }
                          physics Physics {
                            density -1
                            mass 1.721
                            centerOfMass [
                              -0.00136 0.00512 -0.1384
                            ]
                            inertiaMatrix [
                              0.012205 0.012509 0.0020629
                              0 0 0
                            ]
                          }
                          linearVelocity 1.5521068658474014e-09 -3.830668153431978e-08 -1.6279547285269453e-09
                          angularVelocity -6.940672609448513e-08 2.2154632188201838e-08 4.871878429740337e-08
                        }
                      }
                    ]
                    name "right_hip_pitch_link"
                    boundingObject Cylinder {
                      height 0.2
                      radius 0.05
                    }
                    physics Physics {
                      density -1
                      mass 4.152
                      centerOfMass [
                        0.00746 0.02346 -0.08193
                      ]
                      inertiaMatrix [
                        0.082618 0.081579 0.0060081
                        0 0 0
                      ]
                    }
                    linearVelocity 7.965908270043797e-09 -9.695484592504252e-09 -2.8215679521688775e-09
                    angularVelocity -6.898775450446379e-08 1.4558998898562475e-08 4.857010978785662e-08
                  }
                }
              ]
              name "right_hip_roll_link"
              boundingObject Cylinder {
                height 0.01
                radius 0.02
              }
              physics Physics {
                density -1
                mass 2.232
                centerOfMass [
                  -0.0058 0.00319 -9e-05
                ]
                inertiaMatrix [
                  0.0020603 0.0022482 0.0024323
                  0 0 0
                ]
              }
              linearVelocity 4.601738582794079e-09 -5.573714377253362e-09 -8.778697617733386e-09
              angularVelocity -6.819261420025085e-08 6.311412062175217e-11 4.854588114047971e-08
            }
          }
        ]
        name "right_hip_yaw_link"
        boundingObject Cylinder {
          height 0.02
          radius 0.01
        }
        physics Physics {
          density -1
          mass 2.244
          centerOfMass [
            -0.04923 -0.0001 0.0072
          ]
          inertiaMatrix [
            0.0025731 0.0030444 0.0022883
            0 0 0
          ]
        }
        linearVelocity 4.9310414089751e-09 -8.897437905524494e-09 -8.551979224141312e-09
        angularVelocity 2.6472871789332957e-09 1.301270457556763e-10 5.135086648047763e-08
      }
    }
    HingeJoint {
      jointParameters HingeJointParameters {
        position 1.947160250352349e-10
        axis 0 0 1
      }
      device [
        RotationalMotor {
          name "torso_joint"
          maxVelocity 23
          minPosition -2.35
          maxPosition 2.35
          maxTorque 200
        }
        PositionSensor {
          name "torso_joint_sensor"
        }
      ]
      endPoint Solid {
        translation -4.666381431089952e-05 6.134767200983361e-05 -0.001146325914799906
        rotation -0.9182436975295479 0.3865033693166437 0.08627663330326464 0.00012245325305922105
        children [
          DEF torso_link_visual CadShape {
            url [
              "../meshes/torso_link.dae"
            ]
          }
          HingeJoint {
            jointParameters HingeJointParameters {
              position 1.4557557711375457e-08
              axis 0 0.906309 0.422616
              anchor 0.0055 0.15535 0.42999
            }
            device [
              RotationalMotor {
                name "left_shoulder_pitch_joint"
                maxVelocity 9
                minPosition -2.87
                maxPosition 2.87
                maxTorque 75
              }
              PositionSensor {
                name "left_shoulder_pitch_joint_sensor"
              }
            ]
            endPoint Solid {
              translation 0.005500000000000171 0.15535000000000299 0.42999000000000054
              rotation 1 1.5665992477093402e-08 3.4730433547364044e-09 0.43632999999996713
              children [
                DEF left_shoulder_pitch_link_visual CadShape {
                  url [
                    "../meshes/left_shoulder_pitch_link.dae"
                  ]
                }
                HingeJoint {
                  jointParameters HingeJointParameters {
                    position 0.17199999072405642
                    anchor -0.0055 0.0565 -0.0165
                  }
                  device [
                    RotationalMotor {
                      name "left_shoulder_roll_joint"
                      maxVelocity 9
                      minPosition -0.34
                      maxPosition 3.11
                      maxTorque 75
                    }
                    PositionSensor {
                      name "left_shoulder_roll_joint_sensor"
                    }
                  ]
                  endPoint Solid {
                    translation -0.0055000000000002824 0.05649999999999973 -0.01649999999999978
                    rotation -1 -1.090344356333126e-17 -7.626932907868197e-18 0.26433013816702994
                    children [
                      DEF left_shoulder_roll_link_visual CadShape {
                        url [
                          "../meshes/left_shoulder_roll_link.dae"
                        ]
                      }
                      HingeJoint {
                        jointParameters HingeJointParameters {
                          position -0.050000002440351035
                          axis 0 0 1
                          anchor 0 0 -0.1343
                        }
                        device [
                          RotationalMotor {
                            name "left_shoulder_yaw_joint"
                            maxVelocity 20
                            minPosition -1.3
                            maxPosition 4.45
                            maxTorque 75
                          }
                          PositionSensor {
                            name "left_shoulder_yaw_joint_sensor"
                          }
                        ]
                        endPoint Solid {
                          translation 2.8826026654740463e-16 -9.037148271151274e-16 -0.1342999999999992
                          rotation 0 0 -1 0.05000000244035244
                          children [
                            DEF left_shoulder_yaw_link_visual CadShape {
                              url [
                                "../meshes/left_shoulder_yaw_link.dae"
                              ]
                            }
                            HingeJoint {
                              jointParameters HingeJointParameters {
                                position 1.1567001361004526e-08
                                axis 0 1 0
                                anchor 0.0185 0 -0.198
                              }
                              device [
                                RotationalMotor {
                                  name "left_elbow_joint"
                                  maxVelocity 20
                                  minPosition -1.8
                                  maxPosition 3
                                  maxTorque 75
                                }
                                PositionSensor {
                                  name "left_elbow_joint_sensor"
                                }
                              ]
                              endPoint Solid {
                                translation 0.01849999996458654 -1.4921397450962472e-13 -0.19800000088529668
                                rotation 0 1 0 0
                                children [
                                  TouchSensor {
                                    translation 0.27000000947456426 4.905538819599542e-08 -0.020000019862838947
                                    rotation -0.16281224679689638 0.9159770327230535 0.3667127592773617 8.466011488704841e-10
                                    children [
                                      Pose {
                                        translation 0 -0.08 0
                                        rotation 1 0 0 1.57
                                        children [
                                          Solid {
                                            children [
                                              DEF CIRCLE_EE TorusBoundingObject {
                                                majorRadius 0.055
                                                minorRadius 0.01
                                                subdivision 43
                                              }
                                            ]
                                            boundingObject USE CIRCLE_EE
                                            physics Physics {
                                              density -1
                                              mass 0.001
                                            }
                                          }
                                        ]
                                      }
                                      DEF WRIST_TOUCH_SENSOR Shape {
                                        appearance PBRAppearance {
                                          baseColor 0 0 0
                                          roughness 1
                                          metalness 0
                                        }
                                        geometry Sphere {
                                          radius 0.04
                                        }
                                      }
                                    ]
                                    name "left_wrist_touch_sensor_3d"
                                    boundingObject USE WRIST_TOUCH_SENSOR
                                    physics Physics {
                                      density 1
                                    }
                                    type "force-3d"
                                    linearVelocity -9.663918904080858e-09 7.892042601432327e-09 -7.588653697868377e-09
                                    angularVelocity 3.3936378308468236e-09 2.5922130756200168e-12 5.159325983826347e-08
                                  }
                                  DEF left_elbow_link_visual CadShape {
                                    url [
                                      "../meshes/left_elbow_link.dae"
                                    ]
                                  }
                                ]
                                name "left_elbow_link"
                                boundingObject Cylinder {
                                  height 0.09
                                  radius 0.03
                                }
                                physics Physics {
                                  density -1
                                  mass 0.723
                                  centerOfMass [
                                    0.164862 0.000118 -0.015734
                                  ]
                                  inertiaMatrix [
                                    0.00042388 0.0060062 0.0060023
                                    0 0 0
                                  ]
                                }
                                linearVelocity -1.3089954295474899e-08 2.50870595837445e-09 -7.362991147602284e-09
                                angularVelocity 3.3936488217800715e-09 2.590054985636262e-12 5.1593260255445954e-08
                              }
                            }
                          ]
                          name "left_shoulder_yaw_link"
                          boundingObject Cylinder {
                            height 0.01
                            radius 0.04
                          }
                          physics Physics {
                            density -1
                            mass 0.839
                            centerOfMass [
                              0.01365 0.002767 -0.16266
                            ]
                            inertiaMatrix [
                              0.003664 0.0040789 0.00066383
                              0 0 0
                            ]
                          }
                          linearVelocity -1.3179957172650318e-08 -6.483905993471419e-09 -7.356744653793923e-09
                          angularVelocity 3.3934567294753707e-09 -1.6930781208812464e-12 5.159250893716749e-08
                        }
                      }
                    ]
                    name "left_shoulder_roll_link"
                    boundingObject Cylinder {
                      height 0.01
                      radius 0.04
                    }
                    physics Physics {
                      density -1
                      mass 0.793
                      centerOfMass [
                        0.000679 0.00115 -0.094076
                      ]
                      inertiaMatrix [
                        0.0015742 0.0016973 0.0010183
                        0 0 0
                      ]
                    }
                    linearVelocity -1.1336734844099363e-08 -8.241071620073608e-09 -7.478285871459542e-09
                    angularVelocity 3.393466794994781e-09 -1.6898347398917311e-12 5.159251218108021e-08
                  }
                }
              ]
              name "left_shoulder_pitch_link"
              boundingObject Cylinder {
                height 0.04
                radius 0.03
              }
              physics Physics {
                density -1
                mass 1.033
                centerOfMass [
                  0.005045 0.053657 -0.015715
                ]
                inertiaMatrix [
                  0.0012985 0.00087279 0.00097338
                  0 0 0
                ]
              }
              linearVelocity -1.0297744099748114e-08 -8.232601724479646e-09 -7.546645188726073e-09
              angularVelocity 3.3934642501012185e-09 -1.7066508324272178e-12 5.159251117892374e-08
            }
          }
          HingeJoint {
            jointParameters HingeJointParameters {
              position 1.4557921193722705e-08
              axis 0 0.906309 -0.422616
              anchor 0.0055 -0.15535 0.42999
            }
            device [
              RotationalMotor {
                name "right_shoulder_pitch_joint"
                maxVelocity 9
                minPosition -2.87
                maxPosition 2.87
                maxTorque 75
              }
              PositionSensor {
                name "right_shoulder_pitch_joint_sensor"
              }
            ]
            endPoint Solid {
              translation 0.005499999999999949 -0.15534999999999766 0.4299900000000001
              rotation -1 1.5666199647124202e-08 -3.4730927802505956e-09 0.43632999999991895
              children [
                DEF right_shoulder_pitch_link_visual CadShape {
                  url [
                    "../meshes/right_shoulder_pitch_link.dae"
                  ]
                }
                HingeJoint {
                  jointParameters HingeJointParameters {
                    position -0.17199999074324954
                    anchor -0.0055 -0.0565 -0.0165
                  }
                  device [
                    RotationalMotor {
                      name "right_shoulder_roll_joint"
                      maxVelocity 9
                      minPosition -3.11
                      maxPosition 0.34
                      maxTorque 75
                    }
                    PositionSensor {
                      name "right_shoulder_roll_joint_sensor"
                    }
                  ]
                  endPoint Solid {
                    translation -0.005499999999999838 -0.056499999999999655 -0.01649999999999934
                    rotation 1 -4.0573391460830255e-17 1.7881423423633637e-17 0.2643301899183003
                    children [
                      DEF right_shoulder_roll_link_visual CadShape {
                        url [
                          "../meshes/right_shoulder_roll_link.dae"
                        ]
                      }
                      HingeJoint {
                        jointParameters HingeJointParameters {
                          position 0.050000002435682506
                          axis 0 0 1
                          anchor 0 0 -0.1343
                        }
                        device [
                          RotationalMotor {
                            name "right_shoulder_yaw_joint"
                            maxVelocity 20
                            minPosition -4.45
                            maxPosition 1.3
                            maxTorque 75
                          }
                          PositionSensor {
                            name "right_shoulder_yaw_joint_sensor"
                          }
                        ]
                        endPoint Solid {
                          translation 1.1088355365560148e-16 5.548799220011542e-18 -0.13430000000000097
                          rotation 0 0 1 0.05000000243568013
                          children [
                            DEF right_shoulder_yaw_link_visual CadShape {
                              url [
                                "../meshes/right_shoulder_yaw_link.dae"
                              ]
                            }
                            HingeJoint {
                              jointParameters HingeJointParameters {
                                position 1.1569377103039236e-08
                                axis 0 1 0
                                anchor 0.0185 0 -0.198
                              }
                              device [
                                RotationalMotor {
                                  name "right_elbow_joint"
                                  maxVelocity 20
                                  minPosition -2.5
                                  maxPosition 2.61
                                  maxTorque 75
                                }
                                PositionSensor {
                                  name "right_elbow_joint_sensor"
                                }
                              ]
                              endPoint Solid {
                                translation 0.018499999890229723 -4.671818487622769e-13 -0.1980000027441151
                                rotation 0 1 0 0
                                children [
                                  TouchSensor {
                                    translation 0.26999999550624154 -5.2234508274295877e-08 -0.020000029628294946
                                    rotation -0.041144268581299825 0.2948630585318895 0.9546533014011577 1.868079600994798e-09
                                    children [
                                      Pose {
                                        translation 0 0.085 0
                                        rotation 1 0 0 1.57
                                        children [
                                          Solid {
                                            children [
                                              TorusBoundingObject {
                                                majorRadius 0.055
                                                minorRadius 0.01
                                                subdivision 43
                                              }
                                            ]
                                            boundingObject USE CIRCLE_EE
                                            physics Physics {
                                              mass 0.001
                                            }
                                          }
                                        ]
                                      }
                                      DEF WRIST_TOUCH_SENSOR Shape {
                                        appearance PBRAppearance {
                                          baseColor 0 0 0
                                          roughness 1
                                          metalness 0
                                        }
                                        geometry Sphere {
                                          radius 0.04
                                        }
                                      }
                                    ]
                                    name "right_wrist_touch_sensor_3d"
                                    boundingObject USE WRIST_TOUCH_SENSOR
                                    physics Physics {
                                      density 1
                                    }
                                    type "force-3d"
                                    linearVelocity 1.0510592618668747e-08 7.944484783558628e-09 -8.915564774703868e-09
                                    angularVelocity 3.394046268171698e-09 -2.6432287187013867e-13 5.159543221603353e-08
                                  }
                                  DEF right_elbow_link_visual CadShape {
                                    url [
                                      "../meshes/right_elbow_link.dae"
                                    ]
                                  }
                                ]
                                name "right_elbow_link"
                                boundingObject Cylinder {
                                  height 0.09
                                  radius 0.03
                                }
                                physics Physics {
                                  density -1
                                  mass 0.723
                                  centerOfMass [
                                    0.164862 -0.000118 -0.015734
                                  ]
                                  inertiaMatrix [
                                    0.00042388 0.0060062 0.0060023
                                    0 0 0
                                  ]
                                }
                                linearVelocity 1.416642282479709e-08 2.5864209441564344e-09 -9.156140159693773e-09
                                angularVelocity 3.3940334782326624e-09 -2.676642283141348e-13 5.159543264844021e-08
                              }
                            }
                          ]
                          name "right_shoulder_yaw_link"
                          boundingObject Cylinder {
                            height 0.01
                            radius 0.04
                          }
                          physics Physics {
                            density -1
                            mass 0.839
                            centerOfMass [
                              0.01365 -0.002767 -0.16266
                            ]
                            inertiaMatrix [
                              0.003664 0.0040789 0.00066383
                              0 0 0
                            ]
                          }
                          linearVelocity 1.430617782611225e-08 -6.4066384264859605e-09 -9.165188219995993e-09
                          angularVelocity 3.3935234131928164e-09 1.2179902125302843e-11 5.1593242123711506e-08
                        }
                      }
                    ]
                    name "right_shoulder_roll_link"
                    boundingObject Cylinder {
                      height 0.01
                      radius 0.04
                    }
                    physics Physics {
                      density -1
                      mass 0.793
                      centerOfMass [
                        0.000679 -0.00115 -0.094076
                      ]
                      inertiaMatrix [
                        0.0015742 0.0016973 0.0010183
                        0 0 0
                      ]
                    }
                    linearVelocity 1.2474439537377e-08 -8.17468435093084e-09 -9.044358998693177e-09
                    angularVelocity 3.3934846342327745e-09 1.2175731072868236e-11 5.159324204446373e-08
                  }
                }
              ]
              name "right_shoulder_pitch_link"
              boundingObject Cylinder {
                height 0.04
                radius 0.03
              }
              physics Physics {
                density -1
                mass 1.033
                centerOfMass [
                  0.005045 -0.053657 -0.015715
                ]
                inertiaMatrix [
                  0.0012985 0.00087279 0.00097338
                  0 0 0
                ]
              }
              linearVelocity 1.143633966323983e-08 -8.171943591591054e-09 -8.97591736595667e-09
              angularVelocity 3.39348500830757e-09 1.217586867704038e-11 5.1593241107478096e-08
            }
          }
          Solid {
            translation 0.108485 0.0175 0.693171
            rotation -0.6856987715190361 0.6857007715183697 -0.2441959186317357 2.662578
            children [
              Shape {
                appearance DEF d435_left_imager_link_material PBRAppearance {
                  roughness 1
                  metalness 0
                }
                geometry Sphere {
                  radius 0.001
                }
              }
            ]
            name "d435_left_imager_link"
            boundingObject Sphere {
              radius 0.001
            }
            physics Physics {
            }
          }
          Solid {
            translation 0.108485 0.0325 0.693171
            rotation -0.6856987715190361 0.6857007715183697 -0.2441959186317357 2.662578
            children [
              Shape {
                appearance DEF d435_rgb_module_link_material PBRAppearance {
                  roughness 1
                  metalness 0
                }
                geometry Sphere {
                  radius 0.001
                }
              }
            ]
            name "d435_rgb_module_link"
            boundingObject Sphere {
              radius 0.001
            }
            physics Physics {
            }
          }
          Solid {
            translation 0.0473 0 0.674929
            rotation 0 1 0 0.243124
            children [
              Shape {
                appearance DEF mid360_link_material PBRAppearance {
                  roughness 1
                  metalness 0
                }
                geometry Sphere {
                  radius 0.001
                }
              }
            ]
            name "mid360_link"
            boundingObject Sphere {
              radius 0.001
            }
            physics Physics {
            }
          }
        ]
        name "torso_link"
        boundingObject Box {
          size 0.08 0.16 0.1
        }
        physics Physics {
          density -1
          mass 17.789
          centerOfMass [
            0.000489 0.002797 0.20484
          ]
          inertiaMatrix [
            0.4873 0.40963 0.12785
            0 0 0
          ]
        }
        linearVelocity 4.2168268142059857e-10 -7.446414249044798e-09 -8.251670861488842e-09
        angularVelocity 3.3931731023664487e-09 6.0107462603799776e-12 5.159610456128483e-08
      }
    }
  ]
  name "UnitreeH1"
  boundingObject Sphere {
    radius 0.05
  }
  physics Physics {
    density -1
    mass 5.39
    centerOfMass [
      -0.0002 4e-05 -0.04522
    ]
    inertiaMatrix [
      0.044582 0.0082464 0.049021
      0 0 0
    ]
  }
  controller "<extern>"
  supervisor TRUE
  linearVelocity 5.618706011691142e-10 -6.121636031728765e-09 -8.261006057244818e-09
  angularVelocity 3.3931654373407964e-09 5.9987508193726165e-12 5.159629787999937e-08
}
Solid {
  translation -0.28123 -5.05429 0.932446
  rotation 0.1249549627456206 -0.9904577047025079 -0.058135982667195385 -0.03207530717958651
  children [
    Pose {
      children [
        DEF LeftHand Solid {
          translation 7.782108291110035e-13 -0.16699999999990123 0.1099999999755128
          rotation 1 4.954445253319714e-18 -4.906529922049697e-18 1.5708000000000002
          children [
            Shape {
              appearance Cardboard {
                type "front"
              }
              geometry DEF BOX_HAND Cylinder {
                height 0.11
                radius 0.04
              }
            }
          ]
          name "BoxHand1"
          boundingObject USE BOX_HAND
          physics Physics {
            density -1
            mass 0.01
          }
          linearVelocity 0 0 -3.390621117110942e-14
        }
      ]
    }
    Pose {
      children [
        DEF RightHand Solid {
          translation 7.783773625646973e-13 0.15300000000009817 0.10999999997551257
          rotation 1 4.954445253319714e-18 -4.906529922049697e-18 1.5708000000000002
          children [
            Shape {
              appearance Cardboard {
                type "front"
              }
              geometry DEF BOX_HAND Cylinder {
                height 0.12
                radius 0.04
              }
            }
          ]
          name "BoxHand2"
          boundingObject USE BOX_HAND
          physics Physics {
            mass 0.01
          }
          linearVelocity 0 0 -3.390621117110942e-14
        }
      ]
    }
    Shape {
      appearance Cardboard {
        type "front"
      }
      geometry DEF CARRY_BOX Box {
        size 0.25 0.23 0.35
      }
    }
  ]
  name "CarryBox"
  boundingObject USE CARRY_BOX
}
