#VRML_SIM R2023b utf8

EXTERNPROTO "https://raw.githubusercontent.com/cyberbotics/webots/R2023b/projects/objects/backgrounds/protos/TexturedBackground.proto"
EXTERNPROTO "https://raw.githubusercontent.com/cyberbotics/webots/R2023b/projects/objects/backgrounds/protos/TexturedBackgroundLight.proto"
EXTERNPROTO "https://raw.githubusercontent.com/cyberbotics/webots/R2023b/projects/objects/floors/protos/RectangleArena.proto"
EXTERNPROTO "https://raw.githubusercontent.com/cyberbotics/webots/R2023b/projects/objects/advertising_board/protos/AdvertisingBoard.proto"
EXTERNPROTO "https://raw.githubusercontent.com/cyberbotics/webots/R2023b/projects/appearances/protos/Cardboard.proto"
EXTERNPROTO "https://raw.githubusercontent.com/cyberbotics/webots/R2023b/projects/bounding_objects/protos/TorusBoundingObject.proto"
EXTERNPROTO "https://raw.githubusercontent.com/cyberbotics/webots/R2023b/projects/appearances/protos/Parquetry.proto"

WorldInfo {
  gravity 9.8
  CFM 1e-07
  ERP 0.8
  basicTimeStep 1
  FPS 30
  optimalThreadCount 8
  contactProperties [
    ContactProperties {
      coulombFriction [
        0.9
      ]
      bounce 0.3
      bounceVelocity 0.003
      softERP 0.42
      softCFM 0.000208
    }
  ]
}
Viewpoint {
  orientation 0.12664435424965476 0.06673895042663594 -0.9897005203760576 2.1800977563945567
  position 1.1568640057693713 -1.1752844581339312 2.325803771783127
}
TexturedBackground {
}
TexturedBackgroundLight {
  luminosity 0.8
}
RectangleArena {
  translation -0.246845 -3.09843 4.44089e-16
  rotation 0 0 -1 0
  floorSize 50 50
  floorAppearance Parquetry {
    type "light strip"
    colorOverride 0.682353 0.670588 0.662745
  }
}
TexturedBackgroundLight {
  luminosity 0.2
}
AdvertisingBoard {
  translation -1.29955 -6.20696 -4.9738e-14
  rotation 0 0 -1 1.5708
  recognitionColors [
    1 0.847059 0.933333
    0.74902 0.737255 0.741176
  ]
  displayWidth 7
  frameColor 0.666667 0.666667 0.498039
  poleColor 0.862745 0.886275 0.717647
  baseRatio 3
}
DEF UnitreeH1 Robot {
  translation -0.9501929232195045 -5.057005189255756 0.9699267399162287
  rotation 0.008556583117147932 -0.9975074141728726 0.07004101338150714 0.039032994248452656
  children [
    GPS {
      name "gps_upperBody"
    }
    InertialUnit {
      name "inertial_unit_upperBody"
    }
    Gyro {
      name "gyro_upperBody"
    }
    Accelerometer {
      name "accelerometer_upperBody"
    }
    DEF pelvis_visual CadShape {
      url [
        "../meshes/pelvis.dae"
      ]
    }
    HingeJoint {
      jointParameters HingeJointParameters {
        position -5.778315840920832e-08
        axis 0 0 1
        anchor 0 0.0875 -0.1742
      }
      device [
        RotationalMotor {
          name "left_hip_yaw_joint"
          maxVelocity 23
          minPosition -0.43
          maxPosition 0.43
          maxTorque 220
        }
        PositionSensor {
          name "left_hip_yaw_joint_sensor"
        }
      ]
      endPoint Solid {
        translation 1.1102232097021734e-16 0.08750000000000036 -0.17419999999999947
        rotation 0 0 -0.9999999999999999 5.960464477539063e-08
        children [
          DEF left_hip_yaw_link_visual CadShape {
            url [
              "../meshes/left_hip_yaw_link.dae"
            ]
          }
          HingeJoint {
            jointParameters HingeJointParameters {
              position 9.166147407383949e-07
              anchor 0.039468 0 0
            }
            device [
              RotationalMotor {
                name "left_hip_roll_joint"
                maxVelocity 23
                minPosition -0.43
                maxPosition 0.43
                maxTorque 220
              }
              PositionSensor {
                name "left_hip_roll_joint_sensor"
              }
            ]
            endPoint Solid {
              translation 0.039467999999999975 5.551176181930841e-17 -6.661337638924768e-16
              rotation 1 0 0 9.16633397294869e-07
              children [
                DEF left_hip_roll_link_visual CadShape {
                  url [
                    "../meshes/left_hip_roll_link.dae"
                  ]
                }
                HingeJoint {
                  jointParameters HingeJointParameters {
                    position -0.3000001814726911
                    axis 0 1 0
                    anchor 0 0.11536 0
                  }
                  device [
                    RotationalMotor {
                      name "left_hip_pitch_joint"
                      maxVelocity 23
                      minPosition -3.14
                      maxPosition 2.53
                      maxTorque 220
                    }
                    PositionSensor {
                      name "left_hip_pitch_joint_sensor"
                    }
                  ]
                  endPoint Solid {
                    translation 5.551114583200188e-16 0.1153600000000008 2.220447399063614e-16
                    rotation 0 -1 0 0.30000018147269175
                    children [
                      DEF left_hip_pitch_link_visual CadShape {
                        url [
                          "../meshes/left_hip_pitch_link.dae"
                        ]
                      }
                      HingeJoint {
                        jointParameters HingeJointParameters {
                          position 0.8000280066171485
                          axis 0 1 0
                          anchor 0 0 -0.4
                        }
                        device [
                          RotationalMotor {
                            name "left_knee_joint"
                            maxVelocity 14
                            minPosition -0.26
                            maxPosition 2.05
                            maxTorque 360
                          }
                          PositionSensor {
                            name "left_knee_joint_sensor"
                          }
                        ]
                        endPoint Solid {
                          translation -2.1820480173335196e-16 0 -0.40000000000000036
                          rotation 0 0.9999999999999999 0 0.8000280066171482
                          children [
                            DEF left_knee_link_visual CadShape {
                              url [
                                "../meshes/left_knee_link.dae"
                              ]
                            }
                            HingeJoint {
                              jointParameters HingeJointParameters {
                                position -0.461100295205899
                                axis 0 1 0
                                anchor 0 0 -0.4
                              }
                              device [
                                RotationalMotor {
                                  name "left_ankle_joint"
                                  maxVelocity 9
                                  minPosition -0.9000211187369112
                                  maxPosition 0.52
                                  maxTorque 45
                                }
                                PositionSensor {
                                  name "left_ankle_joint_sensor"
                                }
                              ]
                              endPoint DEF LeftFootSole Solid {
                                translation 0.07204001757241928 -1.776356839400253e-15 -0.4200398569896384
                                rotation 0 -1 0 0.46110029520589874
                                children [
                                  TouchSensor {
                                    translation 1.8079443497853731e-09 -7.585439831814256e-09 2.3795715252579452e-07
                                    rotation -0.2465183461059332 0.9637017529737794 0.10250676245233906 4.545675674541412e-09
                                    name "left_foot_sole_touch_sensor_3d"
                                    boundingObject Box {
                                      size 0.28 0.03 0.024
                                    }
                                    physics Physics {
                                      density -1
                                      mass 0.001
                                      centerOfMass [
                                        0 0 0
                                      ]
                                      inertiaMatrix [
                                        1.23e-06 6.581333333333335e-05 6.608333333333334e-05
                                        0 0 0
                                      ]
                                    }
                                    type "force-3d"
                                  }
                                  DEF left_ankle_torque_sensor HingeJoint {
                                    jointParameters HingeJointParameters {
                                      axis 0 1 0
                                    }
                                    device [
                                      RotationalMotor {
                                        name "left_ankle_torque_sensor_pitch"
                                      }
                                    ]
                                    endPoint Solid {
                                      rotation 0 1 0 0
                                      children [
                                        Solid {
                                          children [
                                            Shape {
                                              appearance Appearance {
                                                material Material {
                                                  diffuseColor 0.8 0.129412 0.6
                                                }
                                              }
                                              geometry Box {
                                                size 0.001 0.001 0.001
                                              }
                                            }
                                          ]
                                        }
                                      ]
                                    }
                                  }
                                  Pose {
                                    translation -0.046 0 0.056
                                    children [
                                      DEF left_ankle_link_visual CadShape {
                                        url [
                                          "../meshes/left_ankle_link.dae"
                                        ]
                                      }
                                    ]
                                  }
                                ]
                                name "left_ankle_link"
                                boundingObject Box {
                                  size 0.28 0.03 0.024
                                }
                                physics Physics {
                                  density -1
                                  mass 0.474
                                  centerOfMass [
                                    0.042575 -1e-06 -0.044672
                                  ]
                                  inertiaMatrix [
                                    0.000159668 0.002900286 0.002805438
                                    0 0 0
                                  ]
                                }
                              }
                            }
                          ]
                          name "left_knee_link"
                          boundingObject Cylinder {
                            height 0.2
                            radius 0.05
                          }
                          physics Physics {
                            density -1
                            mass 1.721
                            centerOfMass [
                              -0.00136 -0.00512 -0.1384
                            ]
                            inertiaMatrix [
                              0.012205 0.012509 0.0020629
                              0 0 0
                            ]
                          }
                        }
                      }
                    ]
                    name "left_hip_pitch_link"
                    boundingObject Cylinder {
                      height 0.2
                      radius 0.05
                    }
                    physics Physics {
                      density -1
                      mass 4.152
                      centerOfMass [
                        0.00746 -0.02346 -0.08193
                      ]
                      inertiaMatrix [
                        0.082618 0.081579 0.0060081
                        0 0 0
                      ]
                    }
                  }
                }
              ]
              name "left_hip_roll_link"
              boundingObject Cylinder {
                height 0.01
                radius 0.02
              }
              physics Physics {
                density -1
                mass 2.232
                centerOfMass [
                  -0.0058 -0.00319 -9e-05
                ]
                inertiaMatrix [
                  0.0020603 0.0022482 0.0024323
                  0 0 0
                ]
              }
            }
          }
        ]
        name "left_hip_yaw_link"
        boundingObject Cylinder {
          height 0.02
          radius 0.01
        }
        physics Physics {
          density -1
          mass 2.244
          centerOfMass [
            -0.04923 0.0001 0.0072
          ]
          inertiaMatrix [
            0.0025731 0.0030444 0.0022883
            0 0 0
          ]
        }
      }
    }
    HingeJoint {
      jointParameters HingeJointParameters {
        position 5.745696570999372e-08
        axis 0 0 1
        anchor 0 -0.0875 -0.1742
      }
      device [
        RotationalMotor {
          name "right_hip_yaw_joint"
          maxVelocity 23
          minPosition -0.43
          maxPosition 0.43
          maxTorque 220
        }
        PositionSensor {
          name "right_hip_yaw_joint_sensor"
        }
      ]
      endPoint Solid {
        translation -1.1102232605019e-16 -0.08749999999999947 -0.17419999999999947
        rotation 0 0 1 5.960464477539063e-08
        children [
          DEF right_hip_yaw_link_visual CadShape {
            url [
              "../meshes/right_hip_yaw_link.dae"
            ]
          }
          HingeJoint {
            jointParameters HingeJointParameters {
              position -9.422609763052128e-07
              anchor 0.039468 0 0
            }
            device [
              RotationalMotor {
                name "right_hip_roll_joint"
                maxVelocity 23
                minPosition -0.43
                maxPosition 0.43
                maxTorque 220
              }
              PositionSensor {
                name "right_hip_roll_joint_sensor"
              }
            ]
            endPoint Solid {
              translation 0.03946800000000001 2.775494794372083e-17 -6.661338409278695e-16
              rotation -1 0 0 9.424321830774572e-07
              children [
                DEF right_hip_roll_link_visual CadShape {
                  url [
                    "../meshes/right_hip_roll_link.dae"
                  ]
                }
                HingeJoint {
                  jointParameters HingeJointParameters {
                    position -0.30000019044358933
                    axis 0 1 0
                    anchor 0 -0.11536 0
                  }
                  device [
                    RotationalMotor {
                      name "right_hip_pitch_joint"
                      maxVelocity 23
                      minPosition -3.14
                      maxPosition 2.53
                      maxTorque 220
                    }
                    PositionSensor {
                      name "right_hip_pitch_joint_sensor"
                    }
                  ]
                  endPoint Solid {
                    translation -5.551116811241251e-16 -0.11535999999999635 6.661336740987762e-16
                    rotation 0 -1 0 0.30000019044358905
                    children [
                      DEF right_hip_pitch_link_visual CadShape {
                        url [
                          "../meshes/right_hip_pitch_link.dae"
                        ]
                      }
                      HingeJoint {
                        jointParameters HingeJointParameters {
                          position 0.8000279322644012
                          axis 0 1 0
                          anchor 0 0 -0.4
                        }
                        device [
                          RotationalMotor {
                            name "right_knee_joint"
                            maxVelocity 14
                            minPosition -0.26
                            maxPosition 2.05
                            maxTorque 360
                          }
                          PositionSensor {
                            name "right_knee_joint_sensor"
                          }
                        ]
                        endPoint Solid {
                          translation 3.0439575363705495e-17 -3.552713678800501e-15 -0.40000000000000013
                          rotation 0 0.9999999999999999 0 0.800027932264401
                          children [
                            DEF right_knee_link_visual CadShape {
                              url [
                                "../meshes/right_knee_link.dae"
                              ]
                            }
                            HingeJoint {
                              jointParameters HingeJointParameters {
                                position -0.46109893371779187
                                axis 0 1 0
                                anchor 0 0 -0.4
                              }
                              device [
                                RotationalMotor {
                                  name "right_ankle_joint"
                                  maxVelocity 9
                                  minPosition -0.87
                                  maxPosition 0.52
                                  maxTorque 45
                                }
                                PositionSensor {
                                  name "right_ankle_joint_sensor"
                                }
                              ]
                              endPoint DEF RightFootSole Solid {
                                translation 0.07202193519435025 1.7763568394002647e-15 -0.4199208647116947
                                rotation 0 -1 0 0.46109893371779204
                                children [
                                  TouchSensor {
                                    translation -7.659949452509807e-09 7.50347339817381e-09 2.2635077921891178e-07
                                    rotation -0.21241000947744534 0.9767339877513574 -0.029541581628654227 4.165043045267645e-09
                                    name "right_foot_sole_touch_sensor_3d"
                                    boundingObject Box {
                                      size 0.28 0.03 0.024
                                    }
                                    physics Physics {
                                      density -1
                                      mass 0.001
                                      centerOfMass [
                                        0 0 0
                                      ]
                                      inertiaMatrix [
                                        1.23e-06 6.581333333333335e-05 6.608333333333334e-05
                                        0 0 0
                                      ]
                                    }
                                    type "force-3d"
                                  }
                                  DEF right_ankle_torque_sensor HingeJoint {
                                    jointParameters HingeJointParameters {
                                      axis 0 1 0
                                    }
                                    device [
                                      RotationalMotor {
                                        name "right_ankle_torque_sensor_pitch"
                                      }
                                    ]
                                    endPoint Solid {
                                      rotation 0 1 0 0
                                      children [
                                        Solid {
                                          children [
                                            Shape {
                                              appearance Appearance {
                                                material Material {
                                                  diffuseColor 0.8 0.129412 0.6
                                                }
                                              }
                                              geometry Box {
                                                size 0.001 0.001 0.001
                                              }
                                            }
                                          ]
                                        }
                                      ]
                                    }
                                  }
                                  Pose {
                                    translation -0.046 0 0.056
                                    children [
                                      DEF right_ankle_link_visual CadShape {
                                        url [
                                          "../meshes/right_ankle_link.dae"
                                        ]
                                      }
                                    ]
                                  }
                                ]
                                name "right_ankle_link"
                                boundingObject Box {
                                  size 0.28 0.03 0.024
                                }
                                physics Physics {
                                  density -1
                                  mass 0.474
                                  centerOfMass [
                                    0.042575 1e-06 -0.044672
                                  ]
                                  inertiaMatrix [
                                    0.000159668 0.002900286 0.002805438
                                    0 0 0
                                  ]
                                }
                              }
                            }
                          ]
                          name "right_knee_link"
                          boundingObject Cylinder {
                            height 0.2
                            radius 0.05
                          }
                          physics Physics {
                            density -1
                            mass 1.721
                            centerOfMass [
                              -0.00136 0.00512 -0.1384
                            ]
                            inertiaMatrix [
                              0.012205 0.012509 0.0020629
                              0 0 0
                            ]
                          }
                        }
                      }
                    ]
                    name "right_hip_pitch_link"
                    boundingObject Cylinder {
                      height 0.2
                      radius 0.05
                    }
                    physics Physics {
                      density -1
                      mass 4.152
                      centerOfMass [
                        0.00746 0.02346 -0.08193
                      ]
                      inertiaMatrix [
                        0.082618 0.081579 0.0060081
                        0 0 0
                      ]
                    }
                  }
                }
              ]
              name "right_hip_roll_link"
              boundingObject Cylinder {
                height 0.01
                radius 0.02
              }
              physics Physics {
                density -1
                mass 2.232
                centerOfMass [
                  -0.0058 0.00319 -9e-05
                ]
                inertiaMatrix [
                  0.0020603 0.0022482 0.0024323
                  0 0 0
                ]
              }
            }
          }
        ]
        name "right_hip_yaw_link"
        boundingObject Cylinder {
          height 0.02
          radius 0.01
        }
        physics Physics {
          density -1
          mass 2.244
          centerOfMass [
            -0.04923 -0.0001 0.0072
          ]
          inertiaMatrix [
            0.0025731 0.0030444 0.0022883
            0 0 0
          ]
        }
      }
    }
    HingeJoint {
      jointParameters HingeJointParameters {
        position 1.157548236187566e-08
        axis 0 0 1
      }
      device [
        RotationalMotor {
          name "torso_joint"
          maxVelocity 23
          minPosition -2.35
          maxPosition 2.35
          maxTorque 200
        }
        PositionSensor {
          name "torso_joint_sensor"
        }
      ]
      endPoint Solid {
        translation -4.66638149851978e-05 6.13476714969318e-05 -0.001146325914799906
        rotation -0.9182365853930621 0.3865003697649094 0.08636571899357884 0.0001224541560797847
        children [
          DEF torso_link_visual CadShape {
            url [
              "../meshes/torso_link.dae"
            ]
          }
          HingeJoint {
            jointParameters HingeJointParameters {
              position -9.120805280497002e-07
              axis 0 0.906309 0.422616
              anchor 0.0055 0.15535 0.42999
            }
            device [
              RotationalMotor {
                name "left_shoulder_pitch_joint"
                maxVelocity 9
                minPosition -2.87
                maxPosition 2.87
                maxTorque 75
              }
              PositionSensor {
                name "left_shoulder_pitch_joint_sensor"
              }
            ]
            endPoint Solid {
              translation 0.005500000000000171 0.15535000000000299 0.42999000000000054
              rotation 0.999999999997743 -2.074242707816924e-06 -4.5984547817964106e-07 0.4363300000009305
              children [
                DEF left_shoulder_pitch_link_visual CadShape {
                  url [
                    "../meshes/left_shoulder_pitch_link.dae"
                  ]
                }
                HingeJoint {
                  jointParameters HingeJointParameters {
                    position 0.007754554574264841
                    anchor -0.0055 0.0565 -0.0165
                  }
                  device [
                    RotationalMotor {
                      name "left_shoulder_roll_joint"
                      maxVelocity 9
                      minPosition -0.34
                      maxPosition 3.11
                      maxTorque 75
                    }
                    PositionSensor {
                      name "left_shoulder_roll_joint_sensor"
                    }
                  ]
                  endPoint Solid {
                    translation -0.0055000000000002824 0.05649999999999977 -0.01649999999999974
                    rotation -1 -7.121826862310895e-18 -4.156227650688346e-18 0.4285755743168263
                    children [
                      DEF left_shoulder_roll_link_visual CadShape {
                        url [
                          "../meshes/left_shoulder_roll_link.dae"
                        ]
                      }
                      HingeJoint {
                        jointParameters HingeJointParameters {
                          position 2.613433781552249e-06
                          axis 0 0 1
                          anchor 0 0 -0.1343
                        }
                        device [
                          RotationalMotor {
                            name "left_shoulder_yaw_joint"
                            maxVelocity 20
                            minPosition -1.3
                            maxPosition 4.45
                            maxTorque 75
                          }
                          PositionSensor {
                            name "left_shoulder_yaw_joint_sensor"
                          }
                        ]
                        endPoint Solid {
                          translation 3.3306925595434153e-16 -8.881775389840315e-16 -0.1342999999999992
                          rotation 0 0 0.9999999999999999 2.6134444795126094e-06
                          children [
                            DEF left_shoulder_yaw_link_visual CadShape {
                              url [
                                "../meshes/left_shoulder_yaw_link.dae"
                              ]
                            }
                            HingeJoint {
                              jointParameters HingeJointParameters {
                                position 3.842480359955754e-05
                                axis 0 1 0
                                anchor 0.0185 0 -0.198
                              }
                              device [
                                RotationalMotor {
                                  name "left_elbow_joint"
                                  maxVelocity 20
                                  minPosition -1.8
                                  maxPosition 3
                                  maxTorque 75
                                }
                                PositionSensor {
                                  name "left_elbow_joint_sensor"
                                }
                              ]
                              endPoint Solid {
                                translation 0.01849999996455253 -1.4921397450962536e-13 -0.19800000088529532
                                rotation 0 1 0 3.842479892453255e-05
                                children [
                                  TouchSensor {
                                    translation 0.2700000055991607 5.380574830127216e-08 -0.02000002455919203
                                    rotation -0.1650039172184868 0.9135779040881171 0.37168416762692214 8.403789049351696e-10
                                    children [
                                      Pose {
                                        translation 0 -0.069 0
                                        rotation 1 0 0 1.57
                                        children [
                                          Solid {
                                            children [
                                              DEF CIRCLE_EE TorusBoundingObject {
                                                majorRadius 0.05
                                                minorRadius 0.01
                                                subdivision 43
                                              }
                                            ]
                                            boundingObject USE CIRCLE_EE
                                            physics Physics {
                                              density -1
                                              mass 0.001
                                            }
                                          }
                                        ]
                                      }
                                      DEF WRIST_TOUCH_SENSOR Shape {
                                        appearance PBRAppearance {
                                          baseColor 0 0 0
                                          roughness 1
                                          metalness 0
                                        }
                                        geometry Sphere {
                                          radius 0.04
                                        }
                                      }
                                    ]
                                    name "left_wrist_touch_sensor_3d"
                                    boundingObject USE WRIST_TOUCH_SENSOR
                                    physics Physics {
                                      density 1
                                    }
                                    type "force-3d"
                                  }
                                  DEF left_elbow_link_visual CadShape {
                                    url [
                                      "../meshes/left_elbow_link.dae"
                                    ]
                                  }
                                ]
                                name "left_elbow_link"
                                boundingObject Cylinder {
                                  height 0.09
                                  radius 0.03
                                }
                                physics Physics {
                                  density -1
                                  mass 0.723
                                  centerOfMass [
                                    0.164862 0.000118 -0.015734
                                  ]
                                  inertiaMatrix [
                                    0.00042388 0.0060062 0.0060023
                                    0 0 0
                                  ]
                                }
                              }
                            }
                          ]
                          name "left_shoulder_yaw_link"
                          boundingObject Cylinder {
                            height 0.01
                            radius 0.04
                          }
                          physics Physics {
                            density -1
                            mass 0.839
                            centerOfMass [
                              0.01365 0.002767 -0.16266
                            ]
                            inertiaMatrix [
                              0.003664 0.0040789 0.00066383
                              0 0 0
                            ]
                          }
                        }
                      }
                    ]
                    name "left_shoulder_roll_link"
                    boundingObject Cylinder {
                      height 0.01
                      radius 0.04
                    }
                    physics Physics {
                      density -1
                      mass 0.793
                      centerOfMass [
                        0.000679 0.00115 -0.094076
                      ]
                      inertiaMatrix [
                        0.0015742 0.0016973 0.0010183
                        0 0 0
                      ]
                    }
                  }
                }
              ]
              name "left_shoulder_pitch_link"
              boundingObject Cylinder {
                height 0.04
                radius 0.03
              }
              physics Physics {
                density -1
                mass 1.033
                centerOfMass [
                  0.005045 0.053657 -0.015715
                ]
                inertiaMatrix [
                  0.0012985 0.00087279 0.00097338
                  0 0 0
                ]
              }
            }
          }
          HingeJoint {
            jointParameters HingeJointParameters {
              position 6.485817538906579e-06
              axis 0 0.906309 -0.422616
              anchor 0.0055 -0.15535 0.42999
            }
            device [
              RotationalMotor {
                name "right_shoulder_pitch_joint"
                maxVelocity 9
                minPosition -2.87
                maxPosition 2.87
                maxTorque 75
              }
              PositionSensor {
                name "right_shoulder_pitch_joint_sensor"
              }
            ]
            endPoint Solid {
              translation 0.005499999999999949 -0.15534999999999766 0.4299900000000001
              rotation -0.9999999998880175 1.4610729777786223e-05 -3.239099260482238e-06 0.436330000047251
              children [
                DEF right_shoulder_pitch_link_visual CadShape {
                  url [
                    "../meshes/right_shoulder_pitch_link.dae"
                  ]
                }
                HingeJoint {
                  jointParameters HingeJointParameters {
                    position -0.0005360182217758323
                    anchor -0.0055 -0.0565 -0.0165
                  }
                  device [
                    RotationalMotor {
                      name "right_shoulder_roll_joint"
                      maxVelocity 9
                      minPosition -3.11
                      maxPosition 0.34
                      maxTorque 75
                    }
                    PositionSensor {
                      name "right_shoulder_roll_joint_sensor"
                    }
                  ]
                  endPoint Solid {
                    translation -0.005499999999999838 -0.05649999999999977 -0.016499999999999293
                    rotation 1 -2.5575926595415118e-17 8.742570319694207e-18 0.43579416243978114
                    children [
                      DEF right_shoulder_roll_link_visual CadShape {
                        url [
                          "../meshes/right_shoulder_roll_link.dae"
                        ]
                      }
                      HingeJoint {
                        jointParameters HingeJointParameters {
                          position -5.285883665541701e-06
                          axis 0 0 1
                          anchor 0 0 -0.1343
                        }
                        device [
                          RotationalMotor {
                            name "right_shoulder_yaw_joint"
                            maxVelocity 20
                            minPosition -4.45
                            maxPosition 1.3
                            maxTorque 75
                          }
                          PositionSensor {
                            name "right_shoulder_yaw_joint_sensor"
                          }
                        ]
                        endPoint Solid {
                          translation 1.1102230246094737e-16 -5.90353011904535e-22 -0.13430000000000097
                          rotation 0 0 -1 5.28586007447632e-06
                          children [
                            DEF right_shoulder_yaw_link_visual CadShape {
                              url [
                                "../meshes/right_shoulder_yaw_link.dae"
                              ]
                            }
                            HingeJoint {
                              jointParameters HingeJointParameters {
                                position 4.204519765660471e-05
                                axis 0 1 0
                                anchor 0.0185 0 -0.198
                              }
                              device [
                                RotationalMotor {
                                  name "right_elbow_joint"
                                  maxVelocity 20
                                  minPosition -2.5
                                  maxPosition 2.61
                                  maxTorque 75
                                }
                                PositionSensor {
                                  name "right_elbow_joint_sensor"
                                }
                              ]
                              endPoint Solid {
                                translation 0.018499999890114378 -4.671818487622749e-13 -0.1980000027441105
                                rotation 0 1 0 4.204519416310414e-05
                                children [
                                  TouchSensor {
                                    translation 0.2699999924976174 -5.3984627434999766e-08 -0.020000026603871124
                                    rotation -0.03344821052048179 0.29689564123735956 0.9543239467954446 1.8701774508156806e-09
                                    children [
                                      Pose {
                                        translation 0 0.068 0
                                        rotation 1 0 0 1.57
                                        children [
                                          Solid {
                                            children [
                                              TorusBoundingObject {
                                                majorRadius 0.05
                                                minorRadius 0.01
                                                subdivision 43
                                              }
                                            ]
                                            boundingObject USE CIRCLE_EE
                                            physics Physics {
                                              mass 0.001
                                            }
                                          }
                                        ]
                                      }
                                      DEF WRIST_TOUCH_SENSOR Shape {
                                        appearance PBRAppearance {
                                          baseColor 0 0 0
                                          roughness 1
                                          metalness 0
                                        }
                                        geometry Sphere {
                                          radius 0.04
                                        }
                                      }
                                    ]
                                    name "right_wrist_touch_sensor_3d"
                                    boundingObject USE WRIST_TOUCH_SENSOR
                                    physics Physics {
                                      density 1
                                    }
                                    type "force-3d"
                                  }
                                  DEF right_elbow_link_visual CadShape {
                                    url [
                                      "../meshes/right_elbow_link.dae"
                                    ]
                                  }
                                ]
                                name "right_elbow_link"
                                boundingObject Cylinder {
                                  height 0.09
                                  radius 0.03
                                }
                                physics Physics {
                                  density -1
                                  mass 0.723
                                  centerOfMass [
                                    0.164862 -0.000118 -0.015734
                                  ]
                                  inertiaMatrix [
                                    0.00042388 0.0060062 0.0060023
                                    0 0 0
                                  ]
                                }
                              }
                            }
                          ]
                          name "right_shoulder_yaw_link"
                          boundingObject Cylinder {
                            height 0.01
                            radius 0.04
                          }
                          physics Physics {
                            density -1
                            mass 0.839
                            centerOfMass [
                              0.01365 -0.002767 -0.16266
                            ]
                            inertiaMatrix [
                              0.003664 0.0040789 0.00066383
                              0 0 0
                            ]
                          }
                        }
                      }
                    ]
                    name "right_shoulder_roll_link"
                    boundingObject Cylinder {
                      height 0.01
                      radius 0.04
                    }
                    physics Physics {
                      density -1
                      mass 0.793
                      centerOfMass [
                        0.000679 -0.00115 -0.094076
                      ]
                      inertiaMatrix [
                        0.0015742 0.0016973 0.0010183
                        0 0 0
                      ]
                    }
                  }
                }
              ]
              name "right_shoulder_pitch_link"
              boundingObject Cylinder {
                height 0.04
                radius 0.03
              }
              physics Physics {
                density -1
                mass 1.033
                centerOfMass [
                  0.005045 -0.053657 -0.015715
                ]
                inertiaMatrix [
                  0.0012985 0.00087279 0.00097338
                  0 0 0
                ]
              }
            }
          }
          Solid {
            translation 0.108485 0.0175 0.693171
            rotation -0.6856987715190361 0.6857007715183697 -0.2441959186317357 2.662578
            children [
              Shape {
                appearance DEF d435_left_imager_link_material PBRAppearance {
                  roughness 1
                  metalness 0
                }
                geometry Sphere {
                  radius 0.001
                }
              }
            ]
            name "d435_left_imager_link"
            boundingObject Sphere {
              radius 0.001
            }
            physics Physics {
            }
          }
          Solid {
            translation 0.108485 0.0325 0.693171
            rotation -0.6856987715190361 0.6857007715183697 -0.2441959186317357 2.662578
            children [
              Shape {
                appearance DEF d435_rgb_module_link_material PBRAppearance {
                  roughness 1
                  metalness 0
                }
                geometry Sphere {
                  radius 0.001
                }
              }
            ]
            name "d435_rgb_module_link"
            boundingObject Sphere {
              radius 0.001
            }
            physics Physics {
            }
          }
          Solid {
            translation 0.0473 0 0.674929
            rotation 0 1 0 0.243124
            children [
              Shape {
                appearance DEF mid360_link_material PBRAppearance {
                  roughness 1
                  metalness 0
                }
                geometry Sphere {
                  radius 0.001
                }
              }
            ]
            name "mid360_link"
            boundingObject Sphere {
              radius 0.001
            }
            physics Physics {
            }
          }
        ]
        name "torso_link"
        boundingObject Box {
          size 0.08 0.16 0.1
        }
        physics Physics {
          density -1
          mass 17.789
          centerOfMass [
            0.000489 0.002797 0.20484
          ]
          inertiaMatrix [
            0.4873 0.40963 0.12785
            0 0 0
          ]
        }
      }
    }
  ]
  name "UnitreeH1"
  boundingObject Sphere {
    radius 0.05
  }
  physics Physics {
    density -1
    mass 5.39
    centerOfMass [
      -0.0002 4e-05 -0.04522
    ]
    inertiaMatrix [
      0.044582 0.0082464 0.049021
      0 0 0
    ]
  }
  controller "<extern>"
  supervisor TRUE
}
Solid {
  translation -0.6633430134888458 -5.058570216596698 0.9562730170902862
  rotation -0.08227882529188113 -0.9850028455355885 0.15165615449226422 0.01774228874489686
  children [
    Pose {
      children [
        DEF LeftHand Solid {
          translation 0 -0.136 0.11
          rotation 1 0 0 1.5708
          children [
            Shape {
              appearance Cardboard {
                type "front"
              }
              geometry DEF BOX_HAND Cylinder {
                height 0.063
                radius 0.04
              }
            }
          ]
          name "BoxHand1"
          boundingObject USE BOX_HAND
          physics Physics {
            density -1
            mass 0.01
          }
        }
      ]
    }
    Pose {
      children [
        DEF RightHand Solid {
          translation 0 0.141 0.11
          rotation 1 0 0 1.5708
          children [
            Shape {
              appearance Cardboard {
                type "front"
              }
              geometry DEF BOX_HAND Cylinder {
                height 0.07
                radius 0.04
              }
            }
          ]
          name "BoxHand2"
          boundingObject USE BOX_HAND
          physics Physics {
            mass 0.01
          }
        }
      ]
    }
    Shape {
      appearance Cardboard {
        type "front"
      }
      geometry DEF CARRY_BOX Box {
        size 0.25 0.23 0.35
      }
    }
  ]
  name "CarryBox"
  boundingObject USE CARRY_BOX
  physics Physics {
    density -1
    mass 5
  }
}
