#VRML_SIM R2023b utf8

EXTERNPROTO "https://raw.githubusercontent.com/cyberbotics/webots/R2023b/projects/objects/backgrounds/protos/TexturedBackground.proto"
EXTERNPROTO "https://raw.githubusercontent.com/cyberbotics/webots/R2023b/projects/objects/backgrounds/protos/TexturedBackgroundLight.proto"
EXTERNPROTO "https://raw.githubusercontent.com/cyberbotics/webots/R2023b/projects/objects/floors/protos/RectangleArena.proto"
EXTERNPROTO "https://raw.githubusercontent.com/cyberbotics/webots/R2023b/projects/appearances/protos/Cardboard.proto"
EXTERNPROTO "https://raw.githubusercontent.com/cyberbotics/webots/R2023b/projects/bounding_objects/protos/TorusBoundingObject.proto"
EXTERNPROTO "https://raw.githubusercontent.com/cyberbotics/webots/R2023b/projects/appearances/protos/Parquetry.proto"

WorldInfo {
  gravity 9.8
  CFM 1e-07
  ERP 0.8
  basicTimeStep 1
  FPS 30
  optimalThreadCount 8
  contactProperties [
    ContactProperties {
      coulombFriction [
        0.9
      ]
      bounce 0.3
      bounceVelocity 0.003
      softERP 0.42
      softCFM 0.000208
    }
  ]
}
Viewpoint {
  orientation -0.04726825073458267 0.00285446353574544 0.9988781529848452 3.021757541194765
  position 7.248349974446583 -4.981082364163178 1.449490775966561
}
TexturedBackground {
}
TexturedBackgroundLight {
  luminosity 0.8
}
RectangleArena {
  translation 1.95573 8.31533 4.44089e-16
  rotation 0 0 -1 0
  floorSize 50 50
  floorAppearance Parquetry {
    type "light strip"
    colorOverride 0.682353 0.670588 0.662745
  }
}
TexturedBackgroundLight {
  luminosity 0.2
}
DEF UnitreeH1 Robot {
  translation 0.6875672423321363 -5.052532947031517 0.96993023841476
  rotation 0.008364712565463046 -0.9976412167693177 0.06813247527231431 0.04012119897791043
  children [
    GPS {
      name "gps_upperBody"
    }
    InertialUnit {
      name "inertial_unit_upperBody"
    }
    Gyro {
      name "gyro_upperBody"
    }
    Accelerometer {
      name "accelerometer_upperBody"
    }
    DEF pelvis_visual CadShape {
      url [
        "../meshes/pelvis.dae"
      ]
    }
    HingeJoint {
      jointParameters HingeJointParameters {
        position -7.938747946873695e-09
        axis 0 0 1
        anchor 0 0.0875 -0.1742
      }
      device [
        RotationalMotor {
          name "left_hip_yaw_joint"
          maxVelocity 23
          minPosition -0.43
          maxPosition 0.43
          maxTorque 220
        }
        PositionSensor {
          name "left_hip_yaw_joint_sensor"
        }
      ]
      endPoint Solid {
        translation 1.1102230298496605e-16 0.08750000000000036 -0.17419999999999947
        children [
          DEF left_hip_yaw_link_visual CadShape {
            url [
              "../meshes/left_hip_yaw_link.dae"
            ]
          }
          HingeJoint {
            jointParameters HingeJointParameters {
              position 2.747061433698824e-07
              anchor 0.039468 0 0
            }
            device [
              RotationalMotor {
                name "left_hip_roll_joint"
                maxVelocity 23
                minPosition -0.43
                maxPosition 0.43
                maxTorque 220
              }
              PositionSensor {
                name "left_hip_roll_joint_sensor"
              }
            ]
            endPoint Solid {
              translation 0.039467999999999975 5.551133422230692e-17 -6.661337995258071e-16
              rotation 1 0 0 2.7476383618393225e-07
              children [
                DEF left_hip_roll_link_visual CadShape {
                  url [
                    "../meshes/left_hip_roll_link.dae"
                  ]
                }
                HingeJoint {
                  jointParameters HingeJointParameters {
                    position -0.2999999171128691
                    axis 0 1 0
                    anchor 0 0.11536 0
                  }
                  device [
                    RotationalMotor {
                      name "left_hip_pitch_joint"
                      maxVelocity 23
                      minPosition -3.14
                      maxPosition 2.53
                      maxTorque 220
                    }
                    PositionSensor {
                      name "left_hip_pitch_joint_sensor"
                    }
                  ]
                  endPoint Solid {
                    translation 5.551115170196734e-16 0.1153600000000008 2.2204459315717524e-16
                    rotation 0 -1 0 0.2999999171128687
                    children [
                      DEF left_hip_pitch_link_visual CadShape {
                        url [
                          "../meshes/left_hip_pitch_link.dae"
                        ]
                      }
                      HingeJoint {
                        jointParameters HingeJointParameters {
                          position 0.8000003854867878
                          axis 0 1 0
                          anchor 0 0 -0.4
                        }
                        device [
                          RotationalMotor {
                            name "left_knee_joint"
                            maxVelocity 14
                            minPosition -0.26
                            maxPosition 2.05
                            maxTorque 360
                          }
                          PositionSensor {
                            name "left_knee_joint_sensor"
                          }
                        ]
                        endPoint Solid {
                          translation -2.1820145540958751e-16 0 -0.40000000000000036
                          rotation 0 1 0 0.8000003854867878
                          children [
                            DEF left_knee_link_visual CadShape {
                              url [
                                "../meshes/left_knee_link.dae"
                              ]
                            }
                            HingeJoint {
                              jointParameters HingeJointParameters {
                                position -0.46000005527453036
                                axis 0 1 0
                                anchor 0 0 -0.4
                              }
                              device [
                                RotationalMotor {
                                  name "left_ankle_joint"
                                  maxVelocity 9
                                  minPosition -0.9000211187369112
                                  maxPosition 0.52
                                  maxTorque 45
                                }
                                PositionSensor {
                                  name "left_ankle_joint_sensor"
                                }
                              ]
                              endPoint DEF LeftFootSole Solid {
                                translation 0.07201792532276874 -1.7763568394002106e-15 -0.42011910614823517
                                rotation 0 -1 0 0.46000005527453
                                children [
                                  TouchSensor {
                                    translation 1.8204839857816069e-09 -8.713458399256524e-09 3.8365290323458257e-07
                                    rotation -0.19218471497378753 0.9799681374113486 0.05222532899825754 8.904327975601693e-09
                                    name "left_foot_sole_touch_sensor_3d"
                                    boundingObject Box {
                                      size 0.28 0.03 0.024
                                    }
                                    physics Physics {
                                      density -1
                                      mass 0.001
                                      centerOfMass [
                                        0 0 0
                                      ]
                                      inertiaMatrix [
                                        1.23e-06 6.581333333333335e-05 6.608333333333334e-05
                                        0 0 0
                                      ]
                                    }
                                    type "force-3d"
                                  }
                                  DEF left_ankle_torque_sensor HingeJoint {
                                    jointParameters HingeJointParameters {
                                      axis 0 1 0
                                    }
                                    device [
                                      RotationalMotor {
                                        name "left_ankle_torque_sensor_pitch"
                                      }
                                    ]
                                    endPoint Solid {
                                      rotation 0 1 0 0
                                      children [
                                        Solid {
                                          children [
                                            Shape {
                                              appearance Appearance {
                                                material Material {
                                                  diffuseColor 0.8 0.129412 0.6
                                                }
                                              }
                                              geometry Box {
                                                size 0.001 0.001 0.001
                                              }
                                            }
                                          ]
                                        }
                                      ]
                                    }
                                  }
                                  Pose {
                                    translation -0.046 0 0.056
                                    children [
                                      DEF left_ankle_link_visual CadShape {
                                        url [
                                          "../meshes/left_ankle_link.dae"
                                        ]
                                      }
                                    ]
                                  }
                                ]
                                name "left_ankle_link"
                                boundingObject Box {
                                  size 0.28 0.03 0.024
                                }
                                physics Physics {
                                  density -1
                                  mass 0.474
                                  centerOfMass [
                                    0.042575 -1e-06 -0.044672
                                  ]
                                  inertiaMatrix [
                                    0.000159668 0.002900286 0.002805438
                                    0 0 0
                                  ]
                                }
                              }
                            }
                          ]
                          name "left_knee_link"
                          boundingObject Cylinder {
                            height 0.2
                            radius 0.05
                          }
                          physics Physics {
                            density -1
                            mass 1.721
                            centerOfMass [
                              -0.00136 -0.00512 -0.1384
                            ]
                            inertiaMatrix [
                              0.012205 0.012509 0.0020629
                              0 0 0
                            ]
                          }
                        }
                      }
                    ]
                    name "left_hip_pitch_link"
                    boundingObject Cylinder {
                      height 0.2
                      radius 0.05
                    }
                    physics Physics {
                      density -1
                      mass 4.152
                      centerOfMass [
                        0.00746 -0.02346 -0.08193
                      ]
                      inertiaMatrix [
                        0.082618 0.081579 0.0060081
                        0 0 0
                      ]
                    }
                  }
                }
              ]
              name "left_hip_roll_link"
              boundingObject Cylinder {
                height 0.01
                radius 0.02
              }
              physics Physics {
                density -1
                mass 2.232
                centerOfMass [
                  -0.0058 -0.00319 -9e-05
                ]
                inertiaMatrix [
                  0.0020603 0.0022482 0.0024323
                  0 0 0
                ]
              }
            }
          }
        ]
        name "left_hip_yaw_link"
        boundingObject Cylinder {
          height 0.02
          radius 0.01
        }
        physics Physics {
          density -1
          mass 2.244
          centerOfMass [
            -0.04923 0.0001 0.0072
          ]
          inertiaMatrix [
            0.0025731 0.0030444 0.0022883
            0 0 0
          ]
        }
      }
    }
    HingeJoint {
      jointParameters HingeJointParameters {
        position 8.161730357404775e-09
        axis 0 0 1
        anchor 0 -0.0875 -0.1742
      }
      device [
        RotationalMotor {
          name "right_hip_yaw_joint"
          maxVelocity 23
          minPosition -0.43
          maxPosition 0.43
          maxTorque 220
        }
        PositionSensor {
          name "right_hip_yaw_joint_sensor"
        }
      ]
      endPoint Solid {
        translation -1.1102230004260508e-16 -0.08749999999999947 -0.17419999999999947
        children [
          DEF right_hip_yaw_link_visual CadShape {
            url [
              "../meshes/right_hip_yaw_link.dae"
            ]
          }
          HingeJoint {
            jointParameters HingeJointParameters {
              position -2.8031418651048097e-07
              anchor 0.039468 0 0
            }
            device [
              RotationalMotor {
                name "right_hip_roll_joint"
                maxVelocity 23
                minPosition -0.43
                maxPosition 0.43
                maxTorque 220
              }
              PositionSensor {
                name "right_hip_roll_joint_sensor"
              }
            ]
            endPoint Solid {
              translation 0.03946800000000001 2.7755388888873198e-17 -6.661338225554541e-16
              rotation -1 0 0 2.7957056521316965e-07
              children [
                DEF right_hip_roll_link_visual CadShape {
                  url [
                    "../meshes/right_hip_roll_link.dae"
                  ]
                }
                HingeJoint {
                  jointParameters HingeJointParameters {
                    position -0.29999991580694674
                    axis 0 1 0
                    anchor 0 -0.11536 0
                  }
                  device [
                    RotationalMotor {
                      name "right_hip_pitch_joint"
                      maxVelocity 23
                      minPosition -3.14
                      maxPosition 2.53
                      maxTorque 220
                    }
                    PositionSensor {
                      name "right_hip_pitch_joint_sensor"
                    }
                  ]
                  endPoint Solid {
                    translation -5.55111498179368e-16 -0.11535999999999635 6.661338265527337e-16
                    rotation 0 -1 0 0.2999999158069463
                    children [
                      DEF right_hip_pitch_link_visual CadShape {
                        url [
                          "../meshes/right_hip_pitch_link.dae"
                        ]
                      }
                      HingeJoint {
                        jointParameters HingeJointParameters {
                          position 0.8000003708883224
                          axis 0 1 0
                          anchor 0 0 -0.4
                        }
                        device [
                          RotationalMotor {
                            name "right_knee_joint"
                            maxVelocity 14
                            minPosition -0.26
                            maxPosition 2.05
                            maxTorque 360
                          }
                          PositionSensor {
                            name "right_knee_joint_sensor"
                          }
                        ]
                        endPoint Solid {
                          translation 3.0443450126808204e-17 -3.5527136788004978e-15 -0.40000000000000013
                          rotation 0 0.9999999999999999 0 0.8000003708883223
                          children [
                            DEF right_knee_link_visual CadShape {
                              url [
                                "../meshes/right_knee_link.dae"
                              ]
                            }
                            HingeJoint {
                              jointParameters HingeJointParameters {
                                position -0.4600000487144626
                                axis 0 1 0
                                anchor 0 0 -0.4
                              }
                              device [
                                RotationalMotor {
                                  name "right_ankle_joint"
                                  maxVelocity 9
                                  minPosition -0.87
                                  maxPosition 0.52
                                  maxTorque 45
                                }
                                PositionSensor {
                                  name "right_ankle_joint_sensor"
                                }
                              ]
                              endPoint DEF RightFootSole Solid {
                                translation 0.07200000097429607 1.776356839400303e-15 -0.4199999964925614
                                rotation 0 -1 0 0.4600000487144624
                                children [
                                  TouchSensor {
                                    translation -7.665784895749539e-09 8.711400489858079e-09 3.6540051990240074e-07
                                    rotation -0.17249480722246988 0.9849040472994883 -0.014476156063335712 8.350309261895352e-09
                                    name "right_foot_sole_touch_sensor_3d"
                                    boundingObject Box {
                                      size 0.28 0.03 0.024
                                    }
                                    physics Physics {
                                      density -1
                                      mass 0.001
                                      centerOfMass [
                                        0 0 0
                                      ]
                                      inertiaMatrix [
                                        1.23e-06 6.581333333333335e-05 6.608333333333334e-05
                                        0 0 0
                                      ]
                                    }
                                    type "force-3d"
                                  }
                                  DEF right_ankle_torque_sensor HingeJoint {
                                    jointParameters HingeJointParameters {
                                      axis 0 1 0
                                    }
                                    device [
                                      RotationalMotor {
                                        name "right_ankle_torque_sensor_pitch"
                                      }
                                    ]
                                    endPoint Solid {
                                      rotation 0 1 0 0
                                      children [
                                        Solid {
                                          children [
                                            Shape {
                                              appearance Appearance {
                                                material Material {
                                                  diffuseColor 0.8 0.129412 0.6
                                                }
                                              }
                                              geometry Box {
                                                size 0.001 0.001 0.001
                                              }
                                            }
                                          ]
                                        }
                                      ]
                                    }
                                  }
                                  Pose {
                                    translation -0.046 0 0.056
                                    children [
                                      DEF right_ankle_link_visual CadShape {
                                        url [
                                          "../meshes/right_ankle_link.dae"
                                        ]
                                      }
                                    ]
                                  }
                                ]
                                name "right_ankle_link"
                                boundingObject Box {
                                  size 0.28 0.03 0.024
                                }
                                physics Physics {
                                  density -1
                                  mass 0.474
                                  centerOfMass [
                                    0.042575 1e-06 -0.044672
                                  ]
                                  inertiaMatrix [
                                    0.000159668 0.002900286 0.002805438
                                    0 0 0
                                  ]
                                }
                              }
                            }
                          ]
                          name "right_knee_link"
                          boundingObject Cylinder {
                            height 0.2
                            radius 0.05
                          }
                          physics Physics {
                            density -1
                            mass 1.721
                            centerOfMass [
                              -0.00136 0.00512 -0.1384
                            ]
                            inertiaMatrix [
                              0.012205 0.012509 0.0020629
                              0 0 0
                            ]
                          }
                        }
                      }
                    ]
                    name "right_hip_pitch_link"
                    boundingObject Cylinder {
                      height 0.2
                      radius 0.05
                    }
                    physics Physics {
                      density -1
                      mass 4.152
                      centerOfMass [
                        0.00746 0.02346 -0.08193
                      ]
                      inertiaMatrix [
                        0.082618 0.081579 0.0060081
                        0 0 0
                      ]
                    }
                  }
                }
              ]
              name "right_hip_roll_link"
              boundingObject Cylinder {
                height 0.01
                radius 0.02
              }
              physics Physics {
                density -1
                mass 2.232
                centerOfMass [
                  -0.0058 0.00319 -9e-05
                ]
                inertiaMatrix [
                  0.0020603 0.0022482 0.0024323
                  0 0 0
                ]
              }
            }
          }
        ]
        name "right_hip_yaw_link"
        boundingObject Cylinder {
          height 0.02
          radius 0.01
        }
        physics Physics {
          density -1
          mass 2.244
          centerOfMass [
            -0.04923 -0.0001 0.0072
          ]
          inertiaMatrix [
            0.0025731 0.0030444 0.0022883
            0 0 0
          ]
        }
      }
    }
    HingeJoint {
      jointParameters HingeJointParameters {
        position 1.9458670389219819e-10
        axis 0 0 1
      }
      device [
        RotationalMotor {
          name "torso_joint"
          maxVelocity 23
          minPosition -2.35
          maxPosition 2.35
          maxTorque 200
        }
        PositionSensor {
          name "torso_joint_sensor"
        }
      ]
      endPoint Solid {
        translation -4.666503587782587e-05 6.13476628514216e-05 -0.001146357235751073
        rotation -0.918683908775519 0.3855159751824423 0.08600760801269029 0.00012238146881863132
        children [
          DEF torso_link_visual CadShape {
            url [
              "../meshes/torso_link.dae"
            ]
          }
          HingeJoint {
            jointParameters HingeJointParameters {
              position 1.4438878118322623e-08
              axis 0 0.906309 0.422616
              anchor 0.0055 0.15535 0.42999
            }
            device [
              RotationalMotor {
                name "left_shoulder_pitch_joint"
                maxVelocity 9
                minPosition -2.87
                maxPosition 2.87
                maxTorque 75
              }
              PositionSensor {
                name "left_shoulder_pitch_joint_sensor"
              }
            ]
            endPoint Solid {
              translation 0.005500000000000171 0.15535000000000299 0.42999000000000054
              rotation 1 1.5398326490311958e-08 3.4137036315349392e-09 0.4363299999999271
              children [
                DEF left_shoulder_pitch_link_visual CadShape {
                  url [
                    "../meshes/left_shoulder_pitch_link.dae"
                  ]
                }
                HingeJoint {
                  jointParameters HingeJointParameters {
                    position -3.265343499064821e-10
                    anchor -0.0055 0.0565 -0.0165
                  }
                  device [
                    RotationalMotor {
                      name "left_shoulder_roll_joint"
                      maxVelocity 9
                      minPosition -0.34
                      maxPosition 3.11
                      maxTorque 75
                    }
                    PositionSensor {
                      name "left_shoulder_roll_joint_sensor"
                    }
                  ]
                  endPoint Solid {
                    translation -0.0055000000000002824 0.05649999999999977 -0.016499999999999737
                    rotation -1 -7.012997562598937e-18 -4.05634591953783e-18 0.4363301399932078
                    children [
                      DEF left_shoulder_roll_link_visual CadShape {
                        url [
                          "../meshes/left_shoulder_roll_link.dae"
                        ]
                      }
                      HingeJoint {
                        jointParameters HingeJointParameters {
                          position 6.738018292189868e-12
                          axis 0 0 1
                          anchor 0 0 -0.1343
                        }
                        device [
                          RotationalMotor {
                            name "left_shoulder_yaw_joint"
                            maxVelocity 20
                            minPosition -1.3
                            maxPosition 4.45
                            maxTorque 75
                          }
                          PositionSensor {
                            name "left_shoulder_yaw_joint_sensor"
                          }
                        ]
                        endPoint Solid {
                          translation 3.330669349634955e-16 -8.881784093591387e-16 -0.1342999999999992
                          children [
                            DEF left_shoulder_yaw_link_visual CadShape {
                              url [
                                "../meshes/left_shoulder_yaw_link.dae"
                              ]
                            }
                            HingeJoint {
                              jointParameters HingeJointParameters {
                                position 1.175011631733108e-08
                                axis 0 1 0
                                anchor 0.0185 0 -0.198
                              }
                              device [
                                RotationalMotor {
                                  name "left_elbow_joint"
                                  maxVelocity 20
                                  minPosition -1.8
                                  maxPosition 3
                                  maxTorque 75
                                }
                                PositionSensor {
                                  name "left_elbow_joint_sensor"
                                }
                              ]
                              endPoint Solid {
                                translation 0.01849999996458654 -1.492139745096175e-13 -0.19800000088529668
                                rotation 0 1 0 0
                                children [
                                  TouchSensor {
                                    translation 0.2700000054836953 5.3781120001872296e-08 -0.020000027560737266
                                    rotation -0.1286610045249415 0.9186185352057074 0.3736125435409706 8.328560236447658e-10
                                    children [
                                      DEF Cone Pose {
                                        translation 0 -0.024 0
                                        rotation 1 0 0 -1.5707953071795862
                                        children [
                                          Shape {
                                            appearance Cardboard {
                                              type "front"
                                            }
                                            geometry Cone {
                                              bottomRadius 0.08
                                              height 0.13
                                            }
                                          }
                                        ]
                                      }
                                      Pose {
                                        translation 0 -0.08 0
                                        rotation 1 0 0 1.57
                                        children [
                                          Solid {
                                            children [
                                              DEF CIRCLE_EE TorusBoundingObject {
                                                majorRadius 0.06
                                                minorRadius 0.01
                                                subdivision 43
                                              }
                                            ]
                                            boundingObject USE CIRCLE_EE
                                            physics Physics {
                                              density -1
                                              mass 0.001
                                            }
                                          }
                                        ]
                                      }
                                      DEF WRIST_TOUCH_SENSOR Shape {
                                        appearance PBRAppearance {
                                          baseColor 0 0 0
                                          roughness 1
                                          metalness 0
                                        }
                                        geometry Sphere {
                                          radius 0.04
                                        }
                                      }
                                    ]
                                    name "left_wrist_touch_sensor_3d"
                                    boundingObject USE WRIST_TOUCH_SENSOR
                                    physics Physics {
                                      density 1
                                    }
                                    type "force-3d"
                                  }
                                  DEF left_elbow_link_visual CadShape {
                                    url [
                                      "../meshes/left_elbow_link.dae"
                                    ]
                                  }
                                ]
                                name "left_elbow_link"
                                boundingObject Cylinder {
                                  height 0.09
                                  radius 0.03
                                }
                                physics Physics {
                                  density -1
                                  mass 0.723
                                  centerOfMass [
                                    0.164862 0.000118 -0.015734
                                  ]
                                  inertiaMatrix [
                                    0.00042388 0.0060062 0.0060023
                                    0 0 0
                                  ]
                                }
                              }
                            }
                          ]
                          name "left_shoulder_yaw_link"
                          boundingObject Cylinder {
                            height 0.01
                            radius 0.04
                          }
                          physics Physics {
                            density -1
                            mass 0.839
                            centerOfMass [
                              0.01365 0.002767 -0.16266
                            ]
                            inertiaMatrix [
                              0.003664 0.0040789 0.00066383
                              0 0 0
                            ]
                          }
                        }
                      }
                    ]
                    name "left_shoulder_roll_link"
                    boundingObject Cylinder {
                      height 0.01
                      radius 0.04
                    }
                    physics Physics {
                      density -1
                      mass 0.793
                      centerOfMass [
                        0.000679 0.00115 -0.094076
                      ]
                      inertiaMatrix [
                        0.0015742 0.0016973 0.0010183
                        0 0 0
                      ]
                    }
                  }
                }
              ]
              name "left_shoulder_pitch_link"
              boundingObject Cylinder {
                height 0.04
                radius 0.03
              }
              physics Physics {
                density -1
                mass 1.033
                centerOfMass [
                  0.005045 0.053657 -0.015715
                ]
                inertiaMatrix [
                  0.0012985 0.00087279 0.00097338
                  0 0 0
                ]
              }
            }
          }
          HingeJoint {
            jointParameters HingeJointParameters {
              position 1.4440821024417395e-08
              axis 0 0.906309 -0.422616
              anchor 0.0055 -0.15535 0.42999
            }
            device [
              RotationalMotor {
                name "right_shoulder_pitch_joint"
                maxVelocity 9
                minPosition -2.87
                maxPosition 2.87
                maxTorque 75
              }
              PositionSensor {
                name "right_shoulder_pitch_joint_sensor"
              }
            ]
            endPoint Solid {
              translation 0.005499999999999949 -0.15534999999999766 0.4299900000000001
              rotation -1 1.5402095841612567e-08 -3.4145427717680884e-09 0.43632999999991484
              children [
                DEF right_shoulder_pitch_link_visual CadShape {
                  url [
                    "../meshes/right_shoulder_pitch_link.dae"
                  ]
                }
                HingeJoint {
                  jointParameters HingeJointParameters {
                    position 3.0960517220504056e-10
                    anchor -0.0055 -0.0565 -0.0165
                  }
                  device [
                    RotationalMotor {
                      name "right_shoulder_roll_joint"
                      maxVelocity 9
                      minPosition -3.11
                      maxPosition 0.34
                      maxTorque 75
                    }
                    PositionSensor {
                      name "right_shoulder_roll_joint_sensor"
                    }
                  ]
                  endPoint Solid {
                    translation -0.005499999999999838 -0.05649999999999977 -0.01649999999999929
                    rotation 1 -2.5547345280613885e-17 8.725154013682994e-18 0.4363301911881128
                    children [
                      DEF right_shoulder_roll_link_visual CadShape {
                        url [
                          "../meshes/right_shoulder_roll_link.dae"
                        ]
                      }
                      HingeJoint {
                        jointParameters HingeJointParameters {
                          position -1.1573057725311944e-11
                          axis 0 0 1
                          anchor 0 0 -0.1343
                        }
                        device [
                          RotationalMotor {
                            name "right_shoulder_yaw_joint"
                            maxVelocity 20
                            minPosition -4.45
                            maxPosition 1.3
                            maxTorque 75
                          }
                          PositionSensor {
                            name "right_shoulder_yaw_joint_sensor"
                          }
                        ]
                        endPoint Solid {
                          translation 1.1102230246252068e-16 -3.545722303380709e-24 -0.13430000000000097
                          children [
                            DEF right_shoulder_yaw_link_visual CadShape {
                              url [
                                "../meshes/right_shoulder_yaw_link.dae"
                              ]
                            }
                            HingeJoint {
                              jointParameters HingeJointParameters {
                                position 1.17501160057246e-08
                                axis 0 1 0
                                anchor 0.0185 0 -0.198
                              }
                              device [
                                RotationalMotor {
                                  name "right_elbow_joint"
                                  maxVelocity 20
                                  minPosition -2.5
                                  maxPosition 2.61
                                  maxTorque 75
                                }
                                PositionSensor {
                                  name "right_elbow_joint_sensor"
                                }
                              ]
                              endPoint Solid {
                                translation 0.01849999989022972 -4.671818487622638e-13 -0.1980000027441151
                                rotation 0 1 0 0
                                children [
                                  TouchSensor {
                                    translation 0.2699999923720192 -5.398256952560132e-08 -0.020000029870274272
                                    rotation -0.05234621439124662 0.29769435162149865 0.953225024247455 1.8737557240148108e-09
                                    children [
                                      DEF Cone Pose {
                                        translation 0 0.02 0
                                        rotation -1 0 0 -1.5707953071795862
                                        children [
                                          Shape {
                                            appearance Cardboard {
                                              type "front"
                                            }
                                            geometry Cone {
                                              bottomRadius 0.084
                                              height 0.099
                                            }
                                          }
                                        ]
                                      }
                                      Pose {
                                        translation 0 0.06 0
                                        rotation 1 0 0 1.57
                                        children [
                                          Solid {
                                            children [
                                              TorusBoundingObject {
                                                majorRadius 0.06
                                                minorRadius 0.01
                                                subdivision 43
                                              }
                                            ]
                                            boundingObject USE CIRCLE_EE
                                            physics Physics {
                                              mass 0.001
                                            }
                                          }
                                        ]
                                      }
                                      DEF WRIST_TOUCH_SENSOR Shape {
                                        appearance PBRAppearance {
                                          baseColor 0 0 0
                                          roughness 1
                                          metalness 0
                                        }
                                        geometry Sphere {
                                          radius 0.04
                                        }
                                      }
                                    ]
                                    name "right_wrist_touch_sensor_3d"
                                    boundingObject USE WRIST_TOUCH_SENSOR
                                    physics Physics {
                                      density 1
                                    }
                                    type "force-3d"
                                  }
                                  DEF right_elbow_link_visual CadShape {
                                    url [
                                      "../meshes/right_elbow_link.dae"
                                    ]
                                  }
                                ]
                                name "right_elbow_link"
                                boundingObject Cylinder {
                                  height 0.09
                                  radius 0.03
                                }
                                physics Physics {
                                  density -1
                                  mass 0.723
                                  centerOfMass [
                                    0.164862 -0.000118 -0.015734
                                  ]
                                  inertiaMatrix [
                                    0.00042388 0.0060062 0.0060023
                                    0 0 0
                                  ]
                                }
                              }
                            }
                          ]
                          name "right_shoulder_yaw_link"
                          boundingObject Cylinder {
                            height 0.01
                            radius 0.04
                          }
                          physics Physics {
                            density -1
                            mass 0.839
                            centerOfMass [
                              0.01365 -0.002767 -0.16266
                            ]
                            inertiaMatrix [
                              0.003664 0.0040789 0.00066383
                              0 0 0
                            ]
                          }
                        }
                      }
                    ]
                    name "right_shoulder_roll_link"
                    boundingObject Cylinder {
                      height 0.01
                      radius 0.04
                    }
                    physics Physics {
                      density -1
                      mass 0.793
                      centerOfMass [
                        0.000679 -0.00115 -0.094076
                      ]
                      inertiaMatrix [
                        0.0015742 0.0016973 0.0010183
                        0 0 0
                      ]
                    }
                  }
                }
              ]
              name "right_shoulder_pitch_link"
              boundingObject Cylinder {
                height 0.04
                radius 0.03
              }
              physics Physics {
                density -1
                mass 1.033
                centerOfMass [
                  0.005045 -0.053657 -0.015715
                ]
                inertiaMatrix [
                  0.0012985 0.00087279 0.00097338
                  0 0 0
                ]
              }
            }
          }
          Solid {
            translation 0.108485 0.0175 0.693171
            rotation -0.6856987715190361 0.6857007715183697 -0.2441959186317357 2.662578
            children [
              Shape {
                appearance DEF d435_left_imager_link_material PBRAppearance {
                  roughness 1
                  metalness 0
                }
                geometry Sphere {
                  radius 0.001
                }
              }
            ]
            name "d435_left_imager_link"
            boundingObject Sphere {
              radius 0.001
            }
            physics Physics {
            }
          }
          Solid {
            translation 0.108485 0.0325 0.693171
            rotation -0.6856987715190361 0.6857007715183697 -0.2441959186317357 2.662578
            children [
              Shape {
                appearance DEF d435_rgb_module_link_material PBRAppearance {
                  roughness 1
                  metalness 0
                }
                geometry Sphere {
                  radius 0.001
                }
              }
            ]
            name "d435_rgb_module_link"
            boundingObject Sphere {
              radius 0.001
            }
            physics Physics {
            }
          }
          Solid {
            translation 0.0473 0 0.674929
            rotation 0 1 0 0.243124
            children [
              Shape {
                appearance DEF mid360_link_material PBRAppearance {
                  roughness 1
                  metalness 0
                }
                geometry Sphere {
                  radius 0.001
                }
              }
            ]
            name "mid360_link"
            boundingObject Sphere {
              radius 0.001
            }
            physics Physics {
            }
          }
        ]
        name "torso_link"
        boundingObject Box {
          size 0.08 0.16 0.1
        }
        physics Physics {
          density -1
          mass 17.789
          centerOfMass [
            0.000489 0.002797 0.20484
          ]
          inertiaMatrix [
            0.4873 0.40963 0.12785
            0 0 0
          ]
        }
      }
    }
  ]
  name "UnitreeH1"
  boundingObject Sphere {
    radius 0.05
  }
  physics Physics {
    density -1
    mass 5.39
    centerOfMass [
      -0.0002 4e-05 -0.04522
    ]
    inertiaMatrix [
      0.044582 0.0082464 0.049021
      0 0 0
    ]
  }
  controller "<extern>"
  supervisor TRUE
}
Solid {
  translation -1.9928882071521574 4.141648197878636 0.17498784240000045
  rotation -1.2458477209800657e-06 -2.2940053038431847e-09 0.999999999999224 0.0036826374084874456
  children [
    Pose {
      children [
        DEF LeftHand Solid {
          translation 0 -0.136 0.11
          rotation 1 0 0 1.5708
          children [
            Shape {
              appearance Cardboard {
                type "front"
              }
              geometry DEF BOX_HAND Cylinder {
                height 0.063
                radius 0.04
              }
            }
          ]
          name "BoxHand1"
          boundingObject USE BOX_HAND
          physics Physics {
            density -1
            mass 0.01
          }
        }
      ]
    }
    Pose {
      children [
        DEF RightHand Solid {
          translation 0 0.141 0.11
          rotation 1 0 0 1.5708
          children [
            Shape {
              appearance Cardboard {
                type "front"
              }
              geometry DEF BOX_HAND Cylinder {
                height 0.07
                radius 0.04
              }
            }
          ]
          name "BoxHand2"
          boundingObject USE BOX_HAND
          physics Physics {
            mass 0.01
          }
        }
      ]
    }
    Shape {
      appearance Cardboard {
        type "front"
      }
      geometry DEF CARRY_BOX Box {
        size 0.25 0.23 0.35
      }
    }
  ]
  name "CarryBox"
  boundingObject USE CARRY_BOX
  physics Physics {
    density -1
    mass 10
  }
}
