#VRML_SIM R2023b utf8

EXTERNPROTO "https://raw.githubusercontent.com/cyberbotics/webots/R2023b/projects/objects/backgrounds/protos/TexturedBackground.proto"
EXTERNPROTO "https://raw.githubusercontent.com/cyberbotics/webots/R2023b/projects/objects/backgrounds/protos/TexturedBackgroundLight.proto"
EXTERNPROTO "https://raw.githubusercontent.com/cyberbotics/webots/R2023b/projects/objects/floors/protos/RectangleArena.proto"
EXTERNPROTO "https://raw.githubusercontent.com/cyberbotics/webots/R2023b/projects/objects/advertising_board/protos/AdvertisingBoard.proto"
EXTERNPROTO "https://raw.githubusercontent.com/cyberbotics/webots/R2023b/projects/appearances/protos/Cardboard.proto"
EXTERNPROTO "https://raw.githubusercontent.com/cyberbotics/webots/R2023b/projects/bounding_objects/protos/TorusBoundingObject.proto"
EXTERNPROTO "https://raw.githubusercontent.com/cyberbotics/webots/R2023b/projects/appearances/protos/Parquetry.proto"

WorldInfo {
  gravity 9.8
  CFM 1e-07
  ERP 0.8
  basicTimeStep 1
  FPS 30
  optimalThreadCount 8
  contactProperties [
    ContactProperties {
      coulombFriction [
        0.9
      ]
      bounce 0.3
      bounceVelocity 0.003
      softERP 0.42
      softCFM 0.000208
    }
  ]
}
Viewpoint {
  orientation 0.282364375863802 0.08272635717646375 -0.9557335973331469 2.5955531623764942
  position 1.204379781456252 -3.9519011685313576 2.52801225986254
}
TexturedBackground {
}
TexturedBackgroundLight {
  luminosity 0.8
}
RectangleArena {
  translation -0.246845 -3.09843 4.44089e-16
  rotation 0 0 -1 0
  floorSize 50 50
  floorAppearance Parquetry {
    type "light strip"
    colorOverride 0.682353 0.670588 0.662745
  }
}
TexturedBackgroundLight {
  luminosity 0.2
}
AdvertisingBoard {
  translation -1.29955 -6.20696 -4.9738e-14
  rotation 0 0 -1 1.5708
  recognitionColors [
    1 0.847059 0.933333
    0.74902 0.737255 0.741176
  ]
  displayWidth 7
  frameColor 0.666667 0.666667 0.498039
  poleColor 0.862745 0.886275 0.717647
  baseRatio 3
}
DEF UnitreeH1 Robot {
  translation -0.9511842429585086 -5.057011187493722 0.969929881066402
  rotation 0.00844598418289658 -0.9976397069300911 0.068144555964687 0.040111096845425034
  children [
    GPS {
      name "gps_upperBody"
    }
    InertialUnit {
      name "inertial_unit_upperBody"
    }
    Gyro {
      name "gyro_upperBody"
    }
    Accelerometer {
      name "accelerometer_upperBody"
    }
    DEF pelvis_visual CadShape {
      url [
        "../meshes/pelvis.dae"
      ]
    }
    HingeJoint {
      jointParameters HingeJointParameters {
        position -1.8340108516746206e-08
        axis 0 0 1
        anchor 0 0.0875 -0.1742
      }
      device [
        RotationalMotor {
          name "left_hip_yaw_joint"
          maxVelocity 23
          minPosition -0.43
          maxPosition 0.43
          maxTorque 220
        }
        PositionSensor {
          name "left_hip_yaw_joint_sensor"
        }
      ]
      endPoint Solid {
        translation 1.110223067382819e-16 0.08750000000000036 -0.17419999999999947
        children [
          DEF left_hip_yaw_link_visual CadShape {
            url [
              "../meshes/left_hip_yaw_link.dae"
            ]
          }
          HingeJoint {
            jointParameters HingeJointParameters {
              position 4.6506225874586454e-07
              anchor 0.039468 0 0
            }
            device [
              RotationalMotor {
                name "left_hip_roll_joint"
                maxVelocity 23
                minPosition -0.43
                maxPosition 0.43
                maxTorque 220
              }
              PositionSensor {
                name "left_hip_roll_joint_sensor"
              }
            ]
            endPoint Solid {
              translation 0.039467999999999975 5.551146102494825e-17 -6.661337889588826e-16
              rotation 0.9999999999999999 0 0 4.655271575395269e-07
              children [
                DEF left_hip_roll_link_visual CadShape {
                  url [
                    "../meshes/left_hip_roll_link.dae"
                  ]
                }
                HingeJoint {
                  jointParameters HingeJointParameters {
                    position -0.29999986788115235
                    axis 0 1 0
                    anchor 0 0.11536 0
                  }
                  device [
                    RotationalMotor {
                      name "left_hip_pitch_joint"
                      maxVelocity 23
                      minPosition -3.14
                      maxPosition 2.53
                      maxTorque 220
                    }
                    PositionSensor {
                      name "left_hip_pitch_joint_sensor"
                    }
                  ]
                  endPoint Solid {
                    translation 5.551115279513461e-16 0.1153600000000008 2.2204456582809517e-16
                    rotation 0 -1 0 0.29999986788115224
                    children [
                      DEF left_hip_pitch_link_visual CadShape {
                        url [
                          "../meshes/left_hip_pitch_link.dae"
                        ]
                      }
                      HingeJoint {
                        jointParameters HingeJointParameters {
                          position 0.8000007433743805
                          axis 0 1 0
                          anchor 0 0 -0.4
                        }
                        device [
                          RotationalMotor {
                            name "left_knee_joint"
                            maxVelocity 14
                            minPosition -0.26
                            maxPosition 2.05
                            maxTorque 360
                          }
                          PositionSensor {
                            name "left_knee_joint_sensor"
                          }
                        ]
                        endPoint Solid {
                          translation -2.1820084719830968e-16 0 -0.40000000000000036
                          rotation 0 1 0 0.8000007433743807
                          children [
                            DEF left_knee_link_visual CadShape {
                              url [
                                "../meshes/left_knee_link.dae"
                              ]
                            }
                            HingeJoint {
                              jointParameters HingeJointParameters {
                                position -0.4600001461049008
                                axis 0 1 0
                                anchor 0 0 -0.4
                              }
                              device [
                                RotationalMotor {
                                  name "left_ankle_joint"
                                  maxVelocity 9
                                  minPosition -0.9000211187369112
                                  maxPosition 0.52
                                  maxTorque 45
                                }
                                PositionSensor {
                                  name "left_ankle_joint_sensor"
                                }
                              ]
                              endPoint DEF LeftFootSole Solid {
                                translation 0.07201792715019296 -1.776356839400253e-15 -0.42011909960682
                                rotation 0 -1 0 0.4600001461049007
                                children [
                                  TouchSensor {
                                    translation 1.80933101834313e-09 -7.550473135609082e-09 2.703248683285503e-07
                                    rotation -0.23156278929808927 0.9689752508574098 0.08640392258635472 5.392222816020877e-09
                                    name "left_foot_sole_touch_sensor_3d"
                                    boundingObject Box {
                                      size 0.28 0.03 0.024
                                    }
                                    physics Physics {
                                      density -1
                                      mass 0.001
                                      centerOfMass [
                                        0 0 0
                                      ]
                                      inertiaMatrix [
                                        1.23e-06 6.581333333333335e-05 6.608333333333334e-05
                                        0 0 0
                                      ]
                                    }
                                    type "force-3d"
                                  }
                                  DEF left_ankle_torque_sensor HingeJoint {
                                    jointParameters HingeJointParameters {
                                      axis 0 1 0
                                    }
                                    device [
                                      RotationalMotor {
                                        name "left_ankle_torque_sensor_pitch"
                                      }
                                    ]
                                    endPoint Solid {
                                      rotation 0 1 0 0
                                      children [
                                        Solid {
                                          children [
                                            Shape {
                                              appearance Appearance {
                                                material Material {
                                                  diffuseColor 0.8 0.129412 0.6
                                                }
                                              }
                                              geometry Box {
                                                size 0.001 0.001 0.001
                                              }
                                            }
                                          ]
                                        }
                                      ]
                                    }
                                  }
                                  Pose {
                                    translation -0.046 0 0.056
                                    children [
                                      DEF left_ankle_link_visual CadShape {
                                        url [
                                          "../meshes/left_ankle_link.dae"
                                        ]
                                      }
                                    ]
                                  }
                                ]
                                name "left_ankle_link"
                                boundingObject Box {
                                  size 0.28 0.03 0.024
                                }
                                physics Physics {
                                  density -1
                                  mass 0.474
                                  centerOfMass [
                                    0.042575 -1e-06 -0.044672
                                  ]
                                  inertiaMatrix [
                                    0.000159668 0.002900286 0.002805438
                                    0 0 0
                                  ]
                                }
                              }
                            }
                          ]
                          name "left_knee_link"
                          boundingObject Cylinder {
                            height 0.2
                            radius 0.05
                          }
                          physics Physics {
                            density -1
                            mass 1.721
                            centerOfMass [
                              -0.00136 -0.00512 -0.1384
                            ]
                            inertiaMatrix [
                              0.012205 0.012509 0.0020629
                              0 0 0
                            ]
                          }
                        }
                      }
                    ]
                    name "left_hip_pitch_link"
                    boundingObject Cylinder {
                      height 0.2
                      radius 0.05
                    }
                    physics Physics {
                      density -1
                      mass 4.152
                      centerOfMass [
                        0.00746 -0.02346 -0.08193
                      ]
                      inertiaMatrix [
                        0.082618 0.081579 0.0060081
                        0 0 0
                      ]
                    }
                  }
                }
              ]
              name "left_hip_roll_link"
              boundingObject Cylinder {
                height 0.01
                radius 0.02
              }
              physics Physics {
                density -1
                mass 2.232
                centerOfMass [
                  -0.0058 -0.00319 -9e-05
                ]
                inertiaMatrix [
                  0.0020603 0.0022482 0.0024323
                  0 0 0
                ]
              }
            }
          }
        ]
        name "left_hip_yaw_link"
        boundingObject Cylinder {
          height 0.02
          radius 0.01
        }
        physics Physics {
          density -1
          mass 2.244
          centerOfMass [
            -0.04923 0.0001 0.0072
          ]
          inertiaMatrix [
            0.0025731 0.0030444 0.0022883
            0 0 0
          ]
        }
      }
    }
    HingeJoint {
      jointParameters HingeJointParameters {
        position 1.9792030404151202e-08
        axis 0 0 1
        anchor 0 -0.0875 -0.1742
      }
      device [
        RotationalMotor {
          name "right_hip_yaw_joint"
          maxVelocity 23
          minPosition -0.43
          maxPosition 0.43
          maxTorque 220
        }
        PositionSensor {
          name "right_hip_yaw_joint_sensor"
        }
      ]
      endPoint Solid {
        translation -1.110223061873665e-16 -0.08749999999999947 -0.17419999999999947
        children [
          DEF right_hip_yaw_link_visual CadShape {
            url [
              "../meshes/right_hip_yaw_link.dae"
            ]
          }
          HingeJoint {
            jointParameters HingeJointParameters {
              position -5.001710101632301e-07
              anchor 0.039468 0 0
            }
            device [
              RotationalMotor {
                name "right_hip_roll_joint"
                maxVelocity 23
                minPosition -0.43
                maxPosition 0.43
                maxTorque 220
              }
              PositionSensor {
                name "right_hip_roll_joint_sensor"
              }
            ]
            endPoint Solid {
              translation 0.03946800000000001 2.7755242434805342e-17 -6.661338286576229e-16
              rotation -1 0 0 5.004660971089217e-07
              children [
                DEF right_hip_roll_link_visual CadShape {
                  url [
                    "../meshes/right_hip_roll_link.dae"
                  ]
                }
                HingeJoint {
                  jointParameters HingeJointParameters {
                    position -0.29999986741522006
                    axis 0 1 0
                    anchor 0 -0.11536 0
                  }
                  device [
                    RotationalMotor {
                      name "right_hip_pitch_joint"
                      maxVelocity 23
                      minPosition -3.14
                      maxPosition 2.53
                      maxTorque 220
                    }
                    PositionSensor {
                      name "right_hip_pitch_joint_sensor"
                    }
                  ]
                  endPoint Solid {
                    translation -5.551114659440208e-16 -0.11535999999999635 6.661338534155618e-16
                    rotation 0 -1 0 0.2999998674152195
                    children [
                      DEF right_hip_pitch_link_visual CadShape {
                        url [
                          "../meshes/right_hip_pitch_link.dae"
                        ]
                      }
                      HingeJoint {
                        jointParameters HingeJointParameters {
                          position 0.8000007393840153
                          axis 0 1 0
                          anchor 0 0 -0.4
                        }
                        device [
                          RotationalMotor {
                            name "right_knee_joint"
                            maxVelocity 14
                            minPosition -0.26
                            maxPosition 2.05
                            maxTorque 360
                          }
                          PositionSensor {
                            name "right_knee_joint_sensor"
                          }
                        ]
                        endPoint Solid {
                          translation 3.044330769612076e-17 -3.5527136788004954e-15 -0.40000000000000013
                          rotation 0 1 0 0.8000007393840154
                          children [
                            DEF right_knee_link_visual CadShape {
                              url [
                                "../meshes/right_knee_link.dae"
                              ]
                            }
                            HingeJoint {
                              jointParameters HingeJointParameters {
                                position -0.4600001444378979
                                axis 0 1 0
                                anchor 0 0 -0.4
                              }
                              device [
                                RotationalMotor {
                                  name "right_ankle_joint"
                                  maxVelocity 9
                                  minPosition -0.87
                                  maxPosition 0.52
                                  maxTorque 45
                                }
                                PositionSensor {
                                  name "right_ankle_joint_sensor"
                                }
                              ]
                              endPoint DEF RightFootSole Solid {
                                translation 0.0720000028887624 1.7763568394002714e-15 -0.41999998960047324
                                rotation 0 -1 0 0.4600001444378977
                                children [
                                  TouchSensor {
                                    translation -7.659969214479645e-09 7.48673656403298e-09 2.5852752590441175e-07
                                    rotation -0.20190188384247745 0.9790980265406883 -0.024549617613889133 5.01746807891667e-09
                                    name "right_foot_sole_touch_sensor_3d"
                                    boundingObject Box {
                                      size 0.28 0.03 0.024
                                    }
                                    physics Physics {
                                      density -1
                                      mass 0.001
                                      centerOfMass [
                                        0 0 0
                                      ]
                                      inertiaMatrix [
                                        1.23e-06 6.581333333333335e-05 6.608333333333334e-05
                                        0 0 0
                                      ]
                                    }
                                    type "force-3d"
                                  }
                                  DEF right_ankle_torque_sensor HingeJoint {
                                    jointParameters HingeJointParameters {
                                      axis 0 1 0
                                    }
                                    device [
                                      RotationalMotor {
                                        name "right_ankle_torque_sensor_pitch"
                                      }
                                    ]
                                    endPoint Solid {
                                      rotation 0 1 0 0
                                      children [
                                        Solid {
                                          children [
                                            Shape {
                                              appearance Appearance {
                                                material Material {
                                                  diffuseColor 0.8 0.129412 0.6
                                                }
                                              }
                                              geometry Box {
                                                size 0.001 0.001 0.001
                                              }
                                            }
                                          ]
                                        }
                                      ]
                                    }
                                  }
                                  Pose {
                                    translation -0.046 0 0.056
                                    children [
                                      DEF right_ankle_link_visual CadShape {
                                        url [
                                          "../meshes/right_ankle_link.dae"
                                        ]
                                      }
                                    ]
                                  }
                                ]
                                name "right_ankle_link"
                                boundingObject Box {
                                  size 0.28 0.03 0.024
                                }
                                physics Physics {
                                  density -1
                                  mass 0.474
                                  centerOfMass [
                                    0.042575 1e-06 -0.044672
                                  ]
                                  inertiaMatrix [
                                    0.000159668 0.002900286 0.002805438
                                    0 0 0
                                  ]
                                }
                              }
                            }
                          ]
                          name "right_knee_link"
                          boundingObject Cylinder {
                            height 0.2
                            radius 0.05
                          }
                          physics Physics {
                            density -1
                            mass 1.721
                            centerOfMass [
                              -0.00136 0.00512 -0.1384
                            ]
                            inertiaMatrix [
                              0.012205 0.012509 0.0020629
                              0 0 0
                            ]
                          }
                        }
                      }
                    ]
                    name "right_hip_pitch_link"
                    boundingObject Cylinder {
                      height 0.2
                      radius 0.05
                    }
                    physics Physics {
                      density -1
                      mass 4.152
                      centerOfMass [
                        0.00746 0.02346 -0.08193
                      ]
                      inertiaMatrix [
                        0.082618 0.081579 0.0060081
                        0 0 0
                      ]
                    }
                  }
                }
              ]
              name "right_hip_roll_link"
              boundingObject Cylinder {
                height 0.01
                radius 0.02
              }
              physics Physics {
                density -1
                mass 2.232
                centerOfMass [
                  -0.0058 0.00319 -9e-05
                ]
                inertiaMatrix [
                  0.0020603 0.0022482 0.0024323
                  0 0 0
                ]
              }
            }
          }
        ]
        name "right_hip_yaw_link"
        boundingObject Cylinder {
          height 0.02
          radius 0.01
        }
        physics Physics {
          density -1
          mass 2.244
          centerOfMass [
            -0.04923 -0.0001 0.0072
          ]
          inertiaMatrix [
            0.0025731 0.0030444 0.0022883
            0 0 0
          ]
        }
      }
    }
    HingeJoint {
      jointParameters HingeJointParameters {
        position -1.311499781455466e-09
        axis 0 0 1
      }
      device [
        RotationalMotor {
          name "torso_joint"
          maxVelocity 23
          minPosition -2.35
          maxPosition 2.35
          maxTorque 200
        }
        PositionSensor {
          name "torso_joint_sensor"
        }
      ]
      endPoint Solid {
        translation -4.666381421849676e-05 6.134767208011924e-05 -0.001146325914799906
        rotation -0.9182446720619993 0.3865037803269014 0.08626441921653077 0.00012245312250148014
        children [
          DEF torso_link_visual CadShape {
            url [
              "../meshes/torso_link.dae"
            ]
          }
          HingeJoint {
            jointParameters HingeJointParameters {
              position 4.158994856193756e-08
              axis 0 0.906309 0.422616
              anchor 0.0055 0.15535 0.42999
            }
            device [
              RotationalMotor {
                name "left_shoulder_pitch_joint"
                maxVelocity 9
                minPosition -2.87
                maxPosition 2.87
                maxTorque 75
              }
              PositionSensor {
                name "left_shoulder_pitch_joint_sensor"
              }
            ]
            endPoint Solid {
              translation 0.005500000000000171 0.15535000000000299 0.42999000000000054
              rotation 0.999999999999997 7.663394718840893e-08 1.698922357890857e-08 0.43632999999997846
              children [
                DEF left_shoulder_pitch_link_visual CadShape {
                  url [
                    "../meshes/left_shoulder_pitch_link.dae"
                  ]
                }
                HingeJoint {
                  jointParameters HingeJointParameters {
                    position 0.17199998267942793
                    anchor -0.0055 0.0565 -0.0165
                  }
                  device [
                    RotationalMotor {
                      name "left_shoulder_roll_joint"
                      maxVelocity 9
                      minPosition -0.34
                      maxPosition 3.11
                      maxTorque 75
                    }
                    PositionSensor {
                      name "left_shoulder_roll_joint_sensor"
                    }
                  ]
                  endPoint Solid {
                    translation -0.0055000000000002824 0.05649999999999973 -0.01649999999999978
                    rotation -1 -1.0903443264107823e-17 -7.626932633245917e-18 0.26433014621166123
                    children [
                      DEF left_shoulder_roll_link_visual CadShape {
                        url [
                          "../meshes/left_shoulder_roll_link.dae"
                        ]
                      }
                      HingeJoint {
                        jointParameters HingeJointParameters {
                          position -0.05000000720193904
                          axis 0 0 1
                          anchor 0 0 -0.1343
                        }
                        device [
                          RotationalMotor {
                            name "left_shoulder_yaw_joint"
                            maxVelocity 20
                            minPosition -1.3
                            maxPosition 4.45
                            maxTorque 75
                          }
                          PositionSensor {
                            name "left_shoulder_yaw_joint_sensor"
                          }
                        ]
                        endPoint Solid {
                          translation 2.88260262244288e-16 -9.037148284877069e-16 -0.1342999999999992
                          rotation 0 0 -1 0.050000007201937265
                          children [
                            DEF left_shoulder_yaw_link_visual CadShape {
                              url [
                                "../meshes/left_shoulder_yaw_link.dae"
                              ]
                            }
                            HingeJoint {
                              jointParameters HingeJointParameters {
                                position 3.562314110609137e-08
                                axis 0 1 0
                                anchor 0.0185 0 -0.198
                              }
                              device [
                                RotationalMotor {
                                  name "left_elbow_joint"
                                  maxVelocity 20
                                  minPosition -1.8
                                  maxPosition 3
                                  maxTorque 75
                                }
                                PositionSensor {
                                  name "left_elbow_joint_sensor"
                                }
                              ]
                              endPoint Solid {
                                translation 0.018499999964586518 -1.49213974509625e-13 -0.19800000088529668
                                rotation 0 1 0 2.9802322387695313e-08
                                children [
                                  TouchSensor {
                                    translation 0.27000000558096393 5.3711160852287776e-08 -0.02000002512536403
                                    rotation -0.15945085711477336 0.9152094750664193 0.3700905847411056 8.422332571524327e-10
                                    children [
                                      Pose {
                                        translation 0 -0.08 0
                                        rotation 1 0 0 1.57
                                        children [
                                          Solid {
                                            children [
                                              DEF CIRCLE_EE TorusBoundingObject {
                                                majorRadius 0.055
                                                minorRadius 0.01
                                                subdivision 43
                                              }
                                            ]
                                            boundingObject USE CIRCLE_EE
                                            physics Physics {
                                              density -1
                                              mass 0.001
                                            }
                                          }
                                        ]
                                      }
                                      DEF WRIST_TOUCH_SENSOR Shape {
                                        appearance PBRAppearance {
                                          baseColor 0 0 0
                                          roughness 1
                                          metalness 0
                                        }
                                        geometry Sphere {
                                          radius 0.04
                                        }
                                      }
                                    ]
                                    name "left_wrist_touch_sensor_3d"
                                    boundingObject USE WRIST_TOUCH_SENSOR
                                    physics Physics {
                                      density 1
                                    }
                                    type "force-3d"
                                  }
                                  DEF left_elbow_link_visual CadShape {
                                    url [
                                      "../meshes/left_elbow_link.dae"
                                    ]
                                  }
                                ]
                                name "left_elbow_link"
                                boundingObject Cylinder {
                                  height 0.09
                                  radius 0.03
                                }
                                physics Physics {
                                  density -1
                                  mass 0.723
                                  centerOfMass [
                                    0.164862 0.000118 -0.015734
                                  ]
                                  inertiaMatrix [
                                    0.00042388 0.0060062 0.0060023
                                    0 0 0
                                  ]
                                }
                              }
                            }
                          ]
                          name "left_shoulder_yaw_link"
                          boundingObject Cylinder {
                            height 0.01
                            radius 0.04
                          }
                          physics Physics {
                            density -1
                            mass 0.839
                            centerOfMass [
                              0.01365 0.002767 -0.16266
                            ]
                            inertiaMatrix [
                              0.003664 0.0040789 0.00066383
                              0 0 0
                            ]
                          }
                        }
                      }
                    ]
                    name "left_shoulder_roll_link"
                    boundingObject Cylinder {
                      height 0.01
                      radius 0.04
                    }
                    physics Physics {
                      density -1
                      mass 0.793
                      centerOfMass [
                        0.000679 0.00115 -0.094076
                      ]
                      inertiaMatrix [
                        0.0015742 0.0016973 0.0010183
                        0 0 0
                      ]
                    }
                  }
                }
              ]
              name "left_shoulder_pitch_link"
              boundingObject Cylinder {
                height 0.04
                radius 0.03
              }
              physics Physics {
                density -1
                mass 1.033
                centerOfMass [
                  0.005045 0.053657 -0.015715
                ]
                inertiaMatrix [
                  0.0012985 0.00087279 0.00097338
                  0 0 0
                ]
              }
            }
          }
          HingeJoint {
            jointParameters HingeJointParameters {
              position 9.56169919424564e-08
              axis 0 0.906309 -0.422616
              anchor 0.0055 -0.15535 0.42999
            }
            device [
              RotationalMotor {
                name "right_shoulder_pitch_joint"
                maxVelocity 9
                minPosition -2.87
                maxPosition 2.87
                maxTorque 75
              }
              PositionSensor {
                name "right_shoulder_pitch_joint_sensor"
              }
            ]
            endPoint Solid {
              translation 0.005499999999999949 -0.15534999999999766 0.4299900000000001
              rotation -0.9999999999999793 1.984841301907823e-07 -4.400258255306395e-08 0.4363299999999343
              children [
                DEF right_shoulder_pitch_link_visual CadShape {
                  url [
                    "../meshes/right_shoulder_pitch_link.dae"
                  ]
                }
                HingeJoint {
                  jointParameters HingeJointParameters {
                    position -0.17199998448046666
                    anchor -0.0055 -0.0565 -0.0165
                  }
                  device [
                    RotationalMotor {
                      name "right_shoulder_roll_joint"
                      maxVelocity 9
                      minPosition -3.11
                      maxPosition 0.34
                      maxTorque 75
                    }
                    PositionSensor {
                      name "right_shoulder_roll_joint_sensor"
                    }
                  ]
                  endPoint Solid {
                    translation -0.005499999999999838 -0.056499999999999655 -0.01649999999999934
                    rotation 1 -4.0573390561121284e-17 1.78814228753871e-17 0.2643301961810859
                    children [
                      DEF right_shoulder_roll_link_visual CadShape {
                        url [
                          "../meshes/right_shoulder_roll_link.dae"
                        ]
                      }
                      HingeJoint {
                        jointParameters HingeJointParameters {
                          position 0.05000001762111923
                          axis 0 0 1
                          anchor 0 0 -0.1343
                        }
                        device [
                          RotationalMotor {
                            name "right_shoulder_yaw_joint"
                            maxVelocity 20
                            minPosition -4.45
                            maxPosition 1.3
                            maxTorque 75
                          }
                          PositionSensor {
                            name "right_shoulder_yaw_joint_sensor"
                          }
                        ]
                        endPoint Solid {
                          translation 1.1088355357134008e-16 5.548800903826711e-18 -0.13430000000000097
                          rotation 0 0 1 0.05000001762112191
                          children [
                            DEF right_shoulder_yaw_link_visual CadShape {
                              url [
                                "../meshes/right_shoulder_yaw_link.dae"
                              ]
                            }
                            HingeJoint {
                              jointParameters HingeJointParameters {
                                position 8.948505930300711e-08
                                axis 0 1 0
                                anchor 0.0185 0 -0.198
                              }
                              device [
                                RotationalMotor {
                                  name "right_elbow_joint"
                                  maxVelocity 20
                                  minPosition -2.5
                                  maxPosition 2.61
                                  maxTorque 75
                                }
                                PositionSensor {
                                  name "right_elbow_joint_sensor"
                                }
                              ]
                              endPoint Solid {
                                translation 0.018499999890229508 -4.671818487622749e-13 -0.1980000027441151
                                rotation 0 1 0 8.940696716308595e-08
                                children [
                                  TouchSensor {
                                    translation 0.269999992399081 -5.344888354130717e-08 -0.020000029686489396
                                    rotation -0.04145790796729617 0.29334677554636834 0.95510675379432 1.8677767060839375e-09
                                    children [
                                      Pose {
                                        translation 0 0.068 0
                                        rotation 1 0 0 1.57
                                        children [
                                          Solid {
                                            children [
                                              TorusBoundingObject {
                                                majorRadius 0.055
                                                minorRadius 0.01
                                                subdivision 43
                                              }
                                            ]
                                            boundingObject USE CIRCLE_EE
                                            physics Physics {
                                              mass 0.001
                                            }
                                          }
                                        ]
                                      }
                                      DEF WRIST_TOUCH_SENSOR Shape {
                                        appearance PBRAppearance {
                                          baseColor 0 0 0
                                          roughness 1
                                          metalness 0
                                        }
                                        geometry Sphere {
                                          radius 0.04
                                        }
                                      }
                                    ]
                                    name "right_wrist_touch_sensor_3d"
                                    boundingObject USE WRIST_TOUCH_SENSOR
                                    physics Physics {
                                      density 1
                                    }
                                    type "force-3d"
                                  }
                                  DEF right_elbow_link_visual CadShape {
                                    url [
                                      "../meshes/right_elbow_link.dae"
                                    ]
                                  }
                                ]
                                name "right_elbow_link"
                                boundingObject Cylinder {
                                  height 0.09
                                  radius 0.03
                                }
                                physics Physics {
                                  density -1
                                  mass 0.723
                                  centerOfMass [
                                    0.164862 -0.000118 -0.015734
                                  ]
                                  inertiaMatrix [
                                    0.00042388 0.0060062 0.0060023
                                    0 0 0
                                  ]
                                }
                              }
                            }
                          ]
                          name "right_shoulder_yaw_link"
                          boundingObject Cylinder {
                            height 0.01
                            radius 0.04
                          }
                          physics Physics {
                            density -1
                            mass 0.839
                            centerOfMass [
                              0.01365 -0.002767 -0.16266
                            ]
                            inertiaMatrix [
                              0.003664 0.0040789 0.00066383
                              0 0 0
                            ]
                          }
                        }
                      }
                    ]
                    name "right_shoulder_roll_link"
                    boundingObject Cylinder {
                      height 0.01
                      radius 0.04
                    }
                    physics Physics {
                      density -1
                      mass 0.793
                      centerOfMass [
                        0.000679 -0.00115 -0.094076
                      ]
                      inertiaMatrix [
                        0.0015742 0.0016973 0.0010183
                        0 0 0
                      ]
                    }
                  }
                }
              ]
              name "right_shoulder_pitch_link"
              boundingObject Cylinder {
                height 0.04
                radius 0.03
              }
              physics Physics {
                density -1
                mass 1.033
                centerOfMass [
                  0.005045 -0.053657 -0.015715
                ]
                inertiaMatrix [
                  0.0012985 0.00087279 0.00097338
                  0 0 0
                ]
              }
            }
          }
          Solid {
            translation 0.108485 0.0175 0.693171
            rotation -0.6856987715190361 0.6857007715183697 -0.2441959186317357 2.662578
            children [
              Shape {
                appearance DEF d435_left_imager_link_material PBRAppearance {
                  roughness 1
                  metalness 0
                }
                geometry Sphere {
                  radius 0.001
                }
              }
            ]
            name "d435_left_imager_link"
            boundingObject Sphere {
              radius 0.001
            }
            physics Physics {
            }
          }
          Solid {
            translation 0.108485 0.0325 0.693171
            rotation -0.6856987715190361 0.6857007715183697 -0.2441959186317357 2.662578
            children [
              Shape {
                appearance DEF d435_rgb_module_link_material PBRAppearance {
                  roughness 1
                  metalness 0
                }
                geometry Sphere {
                  radius 0.001
                }
              }
            ]
            name "d435_rgb_module_link"
            boundingObject Sphere {
              radius 0.001
            }
            physics Physics {
            }
          }
          Solid {
            translation 0.0473 0 0.674929
            rotation 0 1 0 0.243124
            children [
              Shape {
                appearance DEF mid360_link_material PBRAppearance {
                  roughness 1
                  metalness 0
                }
                geometry Sphere {
                  radius 0.001
                }
              }
            ]
            name "mid360_link"
            boundingObject Sphere {
              radius 0.001
            }
            physics Physics {
            }
          }
        ]
        name "torso_link"
        boundingObject Box {
          size 0.08 0.16 0.1
        }
        physics Physics {
          density -1
          mass 17.789
          centerOfMass [
            0.000489 0.002797 0.20484
          ]
          inertiaMatrix [
            0.4873 0.40963 0.12785
            0 0 0
          ]
        }
      }
    }
  ]
  name "UnitreeH1"
  boundingObject Sphere {
    radius 0.05
  }
  physics Physics {
    density -1
    mass 5.39
    centerOfMass [
      -0.0002 4e-05 -0.04522
    ]
    inertiaMatrix [
      0.044582 0.0082464 0.049021
      0 0 0
    ]
  }
  controller "<extern>"
  supervisor TRUE
}
Solid {
  translation -0.6749173356470468 -5.072776819317387 0.9428427394702831
  rotation -0.09535622605071738 0.9954312889008756 0.004872292120343207 0.05152284244128785
  children [
    Pose {
      children [
        DEF LeftHand Solid {
          translation 0 -0.127 0.11
          rotation 1 0 0 1.5708
          children [
            Shape {
              appearance Cardboard {
                type "front"
              }
              geometry DEF BOX_HAND Cylinder {
                height 0.15
                radius 0.04
              }
            }
          ]
          name "BoxHand1"
          boundingObject USE BOX_HAND
          physics Physics {
            density -1
            mass 3
          }
        }
      ]
    }
    Pose {
      children [
        DEF RightHand Solid {
          translation 0 0.165 0.11
          rotation 1 0 0 1.5708
          children [
            Shape {
              appearance Cardboard {
                type "front"
              }
              geometry DEF BOX_HAND Cylinder {
                height 0.14
                radius 0.04
              }
            }
          ]
          name "BoxHand2"
          boundingObject USE BOX_HAND
          physics Physics {
            mass 0.01
          }
        }
      ]
    }
    Shape {
      appearance Cardboard {
        type "front"
      }
      geometry DEF CARRY_BOX Box {
        size 0.25 0.23 0.35
      }
    }
  ]
  name "CarryBox"
  boundingObject USE CARRY_BOX
  physics Physics {
    density -1
    mass 0.01
  }
}
